Workbook

Sheet Tổng quan
A1: CTKM FULL THÁNG 10/2026 × TỒN KHO 06/10/2026 – TỔNG QUAN NGÀNH HÀNG
A2: Nguồn: file "CTKM tháng 10.26 và tồn kho 05.10.26" (sheet CTKM T10.26 + Tồn kho 06.10.26). GT tồn tính theo giá KM (nếu trống giá KM: giá BL × (1-%giảm)). Tồn âm tính = 0. Kho LTT = Kho Lê Trọng Tấn (W1099); Kho FC = Kho Franchise_LTTAN (W1082).
A4: Số SKU tham gia CTKM | B4: =COUNTA('Chi tiết SKU'!$D$2:$D$1253) -> 1252
A5: SKU hết hàng toàn hệ thống | B5: =COUNTIF('Chi tiết SKU'!$R$2:$R$1253,"<=0") -> 187
A6: % SKU hết hàng | B6: =B5/B4 -> 0.14936102
A7: Tồn tại CH (sp) | B7: =SUM('Chi tiết SKU'!$M$2:$M$1253) -> 107390
A8: Tồn Kho LTT (sp) | B8: =SUM('Chi tiết SKU'!$N$2:$N$1253) -> 34844
A9: Tồn Kho FC (sp) | B9: =SUM('Chi tiết SKU'!$O$2:$O$1253) -> 10836
A10: GT tồn HT theo giá KM (tỷ đ) | B10: =SUM('Chi tiết SKU'!$T$2:$T$1253)/1000000000 -> 29.108137
A11: …trong đó 1 SKU Thanh massage Stella (tỷ đ) | B11: =SUMIFS('Chi tiết SKU'!$T$2:$T$1253,'Chi tiết SKU'!$D$2:$D$1253,102367)/1000000000 -> 2.823514
A13: Ngành hàng | B13: Số SKU KM | C13: SKU hết hàng | D13: % hết | E13: Tồn CH | F13: Kho LTT | G13: Kho FC | H13: GT tồn giá KM (tr.đ) | I13: % GT | J13: Phủ TB (CH/SKU)
A14: CHĂM SÓC SẮC ĐẸP | B14: =COUNTIFS('Chi tiết SKU'!$B$2:$B$1253,$A14) -> 200 | C14: =COUNTIFS('Chi tiết SKU'!$B$2:$B$1253,$A14,'Chi tiết SKU'!$R$2:$R$1253,"<=0") -> 5 | D14: =IFERROR(C14/B14,0) -> 0.025 | E14: =SUMIFS('Chi tiết SKU'!$M$2:$M$1253,'Chi tiết SKU'!$B$2:$B$1253,$A14) -> 20967 | F14: =SUMIFS('Chi tiết SKU'!$N$2:$N$1253,'Chi tiết SKU'!$B$2:$B$1253,$A14) -> 5582 | G14: =SUMIFS('Chi tiết SKU'!$O$2:$O$1253,'Chi tiết SKU'!$B$2:$B$1253,$A14) -> 2244 | H14: =SUMIFS('Chi tiết SKU'!$T$2:$T$1253,'Chi tiết SKU'!$B$2:$B$1253,$A14)/1000000 -> 8049.873 | I14: =IFERROR(H14/$H$26,0) -> 0.27655061 | J14: =IFERROR(SUMIFS('Chi tiết SKU'!$S$2:$S$1253,'Chi tiết SKU'!$B$2:$B$1253,$A14)/B14,0) -> 17.425
A15: CHĂM SÓC SỨC KHỎE | B15: =COUNTIFS('Chi tiết SKU'!$B$2:$B$1253,$A15) -> 32 | C15: =COUNTIFS('Chi tiết SKU'!$B$2:$B$1253,$A15,'Chi tiết SKU'!$R$2:$R$1253,"<=0") -> 0 | D15: =IFERROR(C15/B15,0) -> 0 | E15: =SUMIFS('Chi tiết SKU'!$M$2:$M$1253,'Chi tiết SKU'!$B$2:$B$1253,$A15) -> 3574 | F15: =SUMIFS('Chi tiết SKU'!$N$2:$N$1253,'Chi tiết SKU'!$B$2:$B$1253,$A15) -> 663 | G15: =SUMIFS('Chi tiết SKU'!$O$2:$O$1253,'Chi tiết SKU'!$B$2:$B$1253,$A15) -> 266 | H15: =SUMIFS('Chi tiết SKU'!$T$2:$T$1253,'Chi tiết SKU'!$B$2:$B$1253,$A15)/1000000 -> 5950.041 | I15: =IFERROR(H15/$H$26,0) -> 0.2044116 | J15: =IFERROR(SUMIFS('Chi tiết SKU'!$S$2:$S$1253,'Chi tiết SKU'!$B$2:$B$1253,$A15)/B15,0) -> 20.125
A16: NHÀ CỬA ĐỜI SỐNG | B16: =COUNTIFS('Chi tiết SKU'!$B$2:$B$1253,$A16) -> 336 | C16: =COUNTIFS('Chi tiết SKU'!$B$2:$B$1253,$A16,'Chi tiết SKU'!$R$2:$R$1253,"<=0") -> 11 | D16: =IFERROR(C16/B16,0) -> 0.032738095 | E16: =SUMIFS('Chi tiết SKU'!$M$2:$M$1253,'Chi tiết SKU'!$B$2:$B$1253,$A16) -> 14788 | F16: =SUMIFS('Chi tiết SKU'!$N$2:$N$1253,'Chi tiết SKU'!$B$2:$B$1253,$A16) -> 5250 | G16: =SUMIFS('Chi tiết SKU'!$O$2:$O$1253,'Chi tiết SKU'!$B$2:$B$1253,$A16) -> 2726 | H16: =SUMIFS('Chi tiết SKU'!$T$2:$T$1253,'Chi tiết SKU'!$B$2:$B$1253,$A16)/1000000 -> 4698.245 | I16: =IFERROR(H16/$H$26,0) -> 0.16140659 | J16: =IFERROR(SUMIFS('Chi tiết SKU'!$S$2:$S$1253,'Chi tiết SKU'!$B$2:$B$1253,$A16)/B16,0) -> 8.4642857
A17: THỜI TRANG | B17: =COUNTIFS('Chi tiết SKU'!$B$2:$B$1253,$A17) -> 422 | C17: =COUNTIFS('Chi tiết SKU'!$B$2:$B$1253,$A17,'Chi tiết SKU'!$R$2:$R$1253,"<=0") -> 137 | D17: =IFERROR(C17/B17,0) -> 0.32464455 | E17: =SUMIFS('Chi tiết SKU'!$M$2:$M$1253,'Chi tiết SKU'!$B$2:$B$1253,$A17) -> 23225 | F17: =SUMIFS('Chi tiết SKU'!$N$2:$N$1253,'Chi tiết SKU'!$B$2:$B$1253,$A17) -> 14011 | G17: =SUMIFS('Chi tiết SKU'!$O$2:$O$1253,'Chi tiết SKU'!$B$2:$B$1253,$A17) -> 0 | H17: =SUMIFS('Chi tiết SKU'!$T$2:$T$1253,'Chi tiết SKU'!$B$2:$B$1253,$A17)/1000000 -> 3869.649 | I17: =IFERROR(H17/$H$26,0) -> 0.13294046 | J17: =IFERROR(SUMIFS('Chi tiết SKU'!$S$2:$S$1253,'Chi tiết SKU'!$B$2:$B$1253,$A17)/B17,0) -> 1.7819905
A18: BỈM | B18: =COUNTIFS('Chi tiết SKU'!$B$2:$B$1253,$A18) -> 59 | C18: =COUNTIFS('Chi tiết SKU'!$B$2:$B$1253,$A18,'Chi tiết SKU'!$R$2:$R$1253,"<=0") -> 33 | D18: =IFERROR(C18/B18,0) -> 0.55932203 | E18: =SUMIFS('Chi tiết SKU'!$M$2:$M$1253,'Chi tiết SKU'!$B$2:$B$1253,$A18) -> 4035 | F18: =SUMIFS('Chi tiết SKU'!$N$2:$N$1253,'Chi tiết SKU'!$B$2:$B$1253,$A18) -> 3039 | G18: =SUMIFS('Chi tiết SKU'!$O$2:$O$1253,'Chi tiết SKU'!$B$2:$B$1253,$A18) -> 313 | H18: =SUMIFS('Chi tiết SKU'!$T$2:$T$1253,'Chi tiết SKU'!$B$2:$B$1253,$A18)/1000000 -> 2111.104 | I18: =IFERROR(H18/$H$26,0) -> 0.072526249 | J18: =IFERROR(SUMIFS('Chi tiết SKU'!$S$2:$S$1253,'Chi tiết SKU'!$B$2:$B$1253,$A18)/B18,0) -> 5.8644068
A19: CHĂM SÓC HÀNG NGÀY | B19: =COUNTIFS('Chi tiết SKU'!$B$2:$B$1253,$A19) -> 77 | C19: =COUNTIFS('Chi tiết SKU'!$B$2:$B$1253,$A19,'Chi tiết SKU'!$R$2:$R$1253,"<=0") -> 0 | D19: =IFERROR(C19/B19,0) -> 0 | E19: =SUMIFS('Chi tiết SKU'!$M$2:$M$1253,'Chi tiết SKU'!$B$2:$B$1253,$A19) -> 14654 | F19: =SUMIFS('Chi tiết SKU'!$N$2:$N$1253,'Chi tiết SKU'!$B$2:$B$1253,$A19) -> 4713 | G19: =SUMIFS('Chi tiết SKU'!$O$2:$O$1253,'Chi tiết SKU'!$B$2:$B$1253,$A19) -> 2765 | H19: =SUMIFS('Chi tiết SKU'!$T$2:$T$1253,'Chi tiết SKU'!$B$2:$B$1253,$A19)/1000000 -> 1679.198 | I19: =IFERROR(H19/$H$26,0) -> 0.057688268 | J19: =IFERROR(SUMIFS('Chi tiết SKU'!$S$2:$S$1253,'Chi tiết SKU'!$B$2:$B$1253,$A19)/B19,0) -> 19.844156
A20: THỰC PHẨM | B20: =COUNTIFS('Chi tiết SKU'!$B$2:$B$1253,$A20) -> 21 | C20: =COUNTIFS('Chi tiết SKU'!$B$2:$B$1253,$A20,'Chi tiết SKU'!$R$2:$R$1253,"<=0") -> 0 | D20: =IFERROR(C20/B20,0) -> 0 | E20: =SUMIFS('Chi tiết SKU'!$M$2:$M$1253,'Chi tiết SKU'!$B$2:$B$1253,$A20) -> 6877 | F20: =SUMIFS('Chi tiết SKU'!$N$2:$N$1253,'Chi tiết SKU'!$B$2:$B$1253,$A20) -> 372 | G20: =SUMIFS('Chi tiết SKU'!$O$2:$O$1253,'Chi tiết SKU'!$B$2:$B$1253,$A20) -> 1587 | H20: =SUMIFS('Chi tiết SKU'!$T$2:$T$1253,'Chi tiết SKU'!$B$2:$B$1253,$A20)/1000000 -> 1288.368 | I20: =IFERROR(H20/$H$26,0) -> 0.044261438 | J20: =IFERROR(SUMIFS('Chi tiết SKU'!$S$2:$S$1253,'Chi tiết SKU'!$B$2:$B$1253,$A20)/B20,0) -> 20.857143
A21: BÁNH NGỌT - TRÁNG MIỆNG | B21: =COUNTIFS('Chi tiết SKU'!$B$2:$B$1253,$A21) -> 46 | C21: =COUNTIFS('Chi tiết SKU'!$B$2:$B$1253,$A21,'Chi tiết SKU'!$R$2:$R$1253,"<=0") -> 1 | D21: =IFERROR(C21/B21,0) -> 0.02173913 | E21: =SUMIFS('Chi tiết SKU'!$M$2:$M$1253,'Chi tiết SKU'!$B$2:$B$1253,$A21) -> 5562 | F21: =SUMIFS('Chi tiết SKU'!$N$2:$N$1253,'Chi tiết SKU'!$B$2:$B$1253,$A21) -> 0 | G21: =SUMIFS('Chi tiết SKU'!$O$2:$O$1253,'Chi tiết SKU'!$B$2:$B$1253,$A21) -> 0 | H21: =SUMIFS('Chi tiết SKU'!$T$2:$T$1253,'Chi tiết SKU'!$B$2:$B$1253,$A21)/1000000 -> 341.55 | I21: =IFERROR(H21/$H$26,0) -> 0.011733832 | J21: =IFERROR(SUMIFS('Chi tiết SKU'!$S$2:$S$1253,'Chi tiết SKU'!$B$2:$B$1253,$A21)/B21,0) -> 7.5217391
A22: ĐỒ CHO MẸ BÉ | B22: =COUNTIFS('Chi tiết SKU'!$B$2:$B$1253,$A22) -> 31 | C22: =COUNTIFS('Chi tiết SKU'!$B$2:$B$1253,$A22,'Chi tiết SKU'!$R$2:$R$1253,"<=0") -> 0 | D22: =IFERROR(C22/B22,0) -> 0 | E22: =SUMIFS('Chi tiết SKU'!$M$2:$M$1253,'Chi tiết SKU'!$B$2:$B$1253,$A22) -> 4449 | F22: =SUMIFS('Chi tiết SKU'!$N$2:$N$1253,'Chi tiết SKU'!$B$2:$B$1253,$A22) -> 1214 | G22: =SUMIFS('Chi tiết SKU'!$O$2:$O$1253,'Chi tiết SKU'!$B$2:$B$1253,$A22) -> 405 | H22: =SUMIFS('Chi tiết SKU'!$T$2:$T$1253,'Chi tiết SKU'!$B$2:$B$1253,$A22)/1000000 -> 329.729 | I22: =IFERROR(H22/$H$26,0) -> 0.011327726 | J22: =IFERROR(SUMIFS('Chi tiết SKU'!$S$2:$S$1253,'Chi tiết SKU'!$B$2:$B$1253,$A22)/B22,0) -> 14.83871
A23: HÀNG ĐÔNG LẠNH | B23: =COUNTIFS('Chi tiết SKU'!$B$2:$B$1253,$A23) -> 3 | C23: =COUNTIFS('Chi tiết SKU'!$B$2:$B$1253,$A23,'Chi tiết SKU'!$R$2:$R$1253,"<=0") -> 0 | D23: =IFERROR(C23/B23,0) -> 0 | E23: =SUMIFS('Chi tiết SKU'!$M$2:$M$1253,'Chi tiết SKU'!$B$2:$B$1253,$A23) -> 2486 | F23: =SUMIFS('Chi tiết SKU'!$N$2:$N$1253,'Chi tiết SKU'!$B$2:$B$1253,$A23) -> 0 | G23: =SUMIFS('Chi tiết SKU'!$O$2:$O$1253,'Chi tiết SKU'!$B$2:$B$1253,$A23) -> 0 | H23: =SUMIFS('Chi tiết SKU'!$T$2:$T$1253,'Chi tiết SKU'!$B$2:$B$1253,$A23)/1000000 -> 291.898 | I23: =IFERROR(H23/$H$26,0) -> 0.010028055 | J23: =IFERROR(SUMIFS('Chi tiết SKU'!$S$2:$S$1253,'Chi tiết SKU'!$B$2:$B$1253,$A23)/B23,0) -> 13.666667
A24: THỰC PHẨM FRESH | B24: =COUNTIFS('Chi tiết SKU'!$B$2:$B$1253,$A24) -> 12 | C24: =COUNTIFS('Chi tiết SKU'!$B$2:$B$1253,$A24,'Chi tiết SKU'!$R$2:$R$1253,"<=0") -> 0 | D24: =IFERROR(C24/B24,0) -> 0 | E24: =SUMIFS('Chi tiết SKU'!$M$2:$M$1253,'Chi tiết SKU'!$B$2:$B$1253,$A24) -> 3709 | F24: =SUMIFS('Chi tiết SKU'!$N$2:$N$1253,'Chi tiết SKU'!$B$2:$B$1253,$A24) -> 0 | G24: =SUMIFS('Chi tiết SKU'!$O$2:$O$1253,'Chi tiết SKU'!$B$2:$B$1253,$A24) -> 0 | H24: =SUMIFS('Chi tiết SKU'!$T$2:$T$1253,'Chi tiết SKU'!$B$2:$B$1253,$A24)/1000000 -> 278.175 | I24: =IFERROR(H24/$H$26,0) -> 0.0095566061 | J24: =IFERROR(SUMIFS('Chi tiết SKU'!$S$2:$S$1253,'Chi tiết SKU'!$B$2:$B$1253,$A24)/B24,0) -> 16.083333
A25: ĐỒ UỐNG | B25: =COUNTIFS('Chi tiết SKU'!$B$2:$B$1253,$A25) -> 13 | C25: =COUNTIFS('Chi tiết SKU'!$B$2:$B$1253,$A25,'Chi tiết SKU'!$R$2:$R$1253,"<=0") -> 0 | D25: =IFERROR(C25/B25,0) -> 0 | E25: =SUMIFS('Chi tiết SKU'!$M$2:$M$1253,'Chi tiết SKU'!$B$2:$B$1253,$A25) -> 3064 | F25: =SUMIFS('Chi tiết SKU'!$N$2:$N$1253,'Chi tiết SKU'!$B$2:$B$1253,$A25) -> 0 | G25: =SUMIFS('Chi tiết SKU'!$O$2:$O$1253,'Chi tiết SKU'!$B$2:$B$1253,$A25) -> 530 | H25: =SUMIFS('Chi tiết SKU'!$T$2:$T$1253,'Chi tiết SKU'!$B$2:$B$1253,$A25)/1000000 -> 220.307 | I25: =IFERROR(H25/$H$26,0) -> 0.0075685709 | J25: =IFERROR(SUMIFS('Chi tiết SKU'!$S$2:$S$1253,'Chi tiết SKU'!$B$2:$B$1253,$A25)/B25,0) -> 12.076923
A26: TỔNG | B26: =SUM(B14:B25) -> 1252 | C26: =SUM(C14:C25) -> 187 | D26: =IFERROR(C26/B26,0) -> 0.14936102 | E26: =SUM(E14:E25) -> 107390 | F26: =SUM(F14:F25) -> 34844 | G26: =SUM(G14:G25) -> 10836 | H26: =SUM(H14:H25) -> 29108.137 | I26: =IFERROR(H26/$H$26,0) -> 1 | J26: =IFERROR(SUMPRODUCT(B14:B25,J14:J25)/B26,0) -> 8.9728435

Sheet Theo CTKM
A1: CTKM T10/26 – ĐỐI CHIẾU TỒN KHO 06/10 THEO TỪNG CHƯƠNG TRÌNH | O1: Ngưỡng
A2: Cờ tự tính: CHẾT (≥80% SKU hết hàng) → ĐẨY XUỐNG CH (Kho LTT ≥200 và ≥ tồn CH) → PHỦ MỎNG (TB < 8 CH có hàng/SKU) → OK. Ngưỡng ở ô bên phải, sửa được. | O2: % SKU hết → CHẾT | P2: 0.8
O3: Kho LTT tối thiểu → ĐẨY | P3: 200
A4: Mã CT | B4: Ngành hàng | C4: Nội dung CTKM | D4: Hình thức | E4: Số SKU | F4: SKU hết hàng HT | G4: Tồn CH | H4: Kho LTT | I4: Kho FC | J4: GT tồn giá KM (đ) | K4: Phủ TB (số CH/SKU) | L4: % giảm (trung vị) | M4: Cờ | N4: Hành động đề xuất | O4: Phủ CH TB → MỎNG | P4: 8
A5: CT001 | B5: THỜI TRANG | C5: Thời trang Nishimatsuya mùa đông giảm ngay 20% | D5: Discount | E5: =COUNTIFS('Chi tiết SKU'!$A$2:$A$1253,$A5) -> 24 | F5: =COUNTIFS('Chi tiết SKU'!$A$2:$A$1253,$A5,'Chi tiết SKU'!$R$2:$R$1253,"<=0") -> 0 | G5: =SUMIFS('Chi tiết SKU'!$M$2:$M$1253,'Chi tiết SKU'!$A$2:$A$1253,$A5) -> 15637 | H5: =SUMIFS('Chi tiết SKU'!$N$2:$N$1253,'Chi tiết SKU'!$A$2:$A$1253,$A5) -> 12191 | I5: =SUMIFS('Chi tiết SKU'!$O$2:$O$1253,'Chi tiết SKU'!$A$2:$A$1253,$A5) -> 0 | J5: =SUMIFS('Chi tiết SKU'!$T$2:$T$1253,'Chi tiết SKU'!$A$2:$A$1253,$A5) -> 3219708000 | K5: =IFERROR(SUMIFS('Chi tiết SKU'!$S$2:$S$1253,'Chi tiết SKU'!$A$2:$A$1253,$A5)/E5,0) -> 7.25 | L5: 0.2 | M5: =IF(F5/E5>=$P$2,"CHẾT – hết hàng",IF(AND(H5>=$P$3,H5>=G5),"ĐẨY XUỐNG CH",IF(K5<$P$4,"PHỦ MỎNG","OK"))) -> PHỦ MỎNG | N5: Mùa lạnh bắt đầu cuối T10: đẩy ngay kho LTT xuống CH (ưu tiên CH khu dân cư/trẻ em), trưng bày mặt tiền từ 15/10.
A6: CT017 | B6: CHĂM SÓC SẮC ĐẸP | C6: Thanh Massage giá 6500k -> 1199K (tặng ngay serum retinol 230689) trị giá 350K | D6: Mua hàng tặng hàng | E6: =COUNTIFS('Chi tiết SKU'!$A$2:$A$1253,$A6) -> 1 | F6: =COUNTIFS('Chi tiết SKU'!$A$2:$A$1253,$A6,'Chi tiết SKU'!$R$2:$R$1253,"<=0") -> 0 | G6: =SUMIFS('Chi tiết SKU'!$M$2:$M$1253,'Chi tiết SKU'!$A$2:$A$1253,$A6) -> 221 | H6: =SUMIFS('Chi tiết SKU'!$N$2:$N$1253,'Chi tiết SKU'!$A$2:$A$1253,$A6) -> 2324 | I6: =SUMIFS('Chi tiết SKU'!$O$2:$O$1253,'Chi tiết SKU'!$A$2:$A$1253,$A6) -> 0 | J6: =SUMIFS('Chi tiết SKU'!$T$2:$T$1253,'Chi tiết SKU'!$A$2:$A$1253,$A6) -> 2823514000 | K6: =IFERROR(SUMIFS('Chi tiết SKU'!$S$2:$S$1253,'Chi tiết SKU'!$A$2:$A$1253,$A6)/E6,0) -> 23 | L6: 0.82938 | M6: =IF(F6/E6>=$P$2,"CHẾT – hết hàng",IF(AND(H6>=$P$3,H6>=G6),"ĐẨY XUỐNG CH",IF(K6<$P$4,"PHỦ MỎNG","OK"))) -> ĐẨY XUỐNG CH | N6: Kho LTT còn 2,324 > tồn CH 221: lệnh điều chuyển bổ sung xuống CH trong tuần này, nhất là CH đang 0.
A7: CT010 | B7: NHÀ CỬA ĐỜI SỐNG | C7: Gia dụng KAIYO đồng giảm 10% | D7: Discount | E7: =COUNTIFS('Chi tiết SKU'!$A$2:$A$1253,$A7) -> 174 | F7: =COUNTIFS('Chi tiết SKU'!$A$2:$A$1253,$A7,'Chi tiết SKU'!$R$2:$R$1253,"<=0") -> 1 | G7: =SUMIFS('Chi tiết SKU'!$M$2:$M$1253,'Chi tiết SKU'!$A$2:$A$1253,$A7) -> 3528 | H7: =SUMIFS('Chi tiết SKU'!$N$2:$N$1253,'Chi tiết SKU'!$A$2:$A$1253,$A7) -> 1 | I7: =SUMIFS('Chi tiết SKU'!$O$2:$O$1253,'Chi tiết SKU'!$A$2:$A$1253,$A7) -> 454 | J7: =SUMIFS('Chi tiết SKU'!$T$2:$T$1253,'Chi tiết SKU'!$A$2:$A$1253,$A7) -> 2017280000 | K7: =IFERROR(SUMIFS('Chi tiết SKU'!$S$2:$S$1253,'Chi tiết SKU'!$A$2:$A$1253,$A7)/E7,0) -> 6.9195402 | L7: 0.1 | M7: =IF(F7/E7>=$P$2,"CHẾT – hết hàng",IF(AND(H7>=$P$3,H7>=G7),"ĐẨY XUỐNG CH",IF(K7<$P$4,"PHỦ MỎNG","OK"))) -> PHỦ MỎNG | N7: Long-tail nhiều SKU, phủ thấp: chọn top 20 SKU bán chạy làm đảo/kệ đầu; còn lại giữ kệ thường + tag giảm 10%.
A8: CT043 | B8: CHĂM SÓC SỨC KHỎE | C8: TPCN NMN Ikimoto giá 4500k->2999K, mua 2 tặng 1 . Mua bất kì SL được tặng ngay 1 túi thương hiệu Ikomoto | D8: Combo | E8: =COUNTIFS('Chi tiết SKU'!$A$2:$A$1253,$A8) -> 1 | F8: =COUNTIFS('Chi tiết SKU'!$A$2:$A$1253,$A8,'Chi tiết SKU'!$R$2:$R$1253,"<=0") -> 0 | G8: =SUMIFS('Chi tiết SKU'!$M$2:$M$1253,'Chi tiết SKU'!$A$2:$A$1253,$A8) -> 242 | H8: =SUMIFS('Chi tiết SKU'!$N$2:$N$1253,'Chi tiết SKU'!$A$2:$A$1253,$A8) -> 560 | I8: =SUMIFS('Chi tiết SKU'!$O$2:$O$1253,'Chi tiết SKU'!$A$2:$A$1253,$A8) -> 24 | J8: =SUMIFS('Chi tiết SKU'!$T$2:$T$1253,'Chi tiết SKU'!$A$2:$A$1253,$A8) -> 1683158000 | K8: =IFERROR(SUMIFS('Chi tiết SKU'!$S$2:$S$1253,'Chi tiết SKU'!$A$2:$A$1253,$A8)/E8,0) -> 24 | L8: 0.5557 | M8: =IF(F8/E8>=$P$2,"CHẾT – hết hàng",IF(AND(H8>=$P$3,H8>=G8),"ĐẨY XUỐNG CH",IF(K8<$P$4,"PHỦ MỎNG","OK"))) -> ĐẨY XUỐNG CH | N8: Kho LTT còn 560 > tồn CH 242: lệnh điều chuyển bổ sung xuống CH trong tuần này, nhất là CH đang 0.
A9: CT006 | B9: BỈM | C9: Bỉm Anyzoo giảm 15K/bịch, mua từ 2 giảm 40K/bịch | D9: Mua càng nhiều giá càng rẻ | E9: =COUNTIFS('Chi tiết SKU'!$A$2:$A$1253,$A9) -> 7 | F9: =COUNTIFS('Chi tiết SKU'!$A$2:$A$1253,$A9,'Chi tiết SKU'!$R$2:$R$1253,"<=0") -> 0 | G9: =SUMIFS('Chi tiết SKU'!$M$2:$M$1253,'Chi tiết SKU'!$A$2:$A$1253,$A9) -> 2329 | H9: =SUMIFS('Chi tiết SKU'!$N$2:$N$1253,'Chi tiết SKU'!$A$2:$A$1253,$A9) -> 2776 | I9: =SUMIFS('Chi tiết SKU'!$O$2:$O$1253,'Chi tiết SKU'!$A$2:$A$1253,$A9) -> 174 | J9: =SUMIFS('Chi tiết SKU'!$T$2:$T$1253,'Chi tiết SKU'!$A$2:$A$1253,$A9) -> 1349481000 | K9: =IFERROR(SUMIFS('Chi tiết SKU'!$S$2:$S$1253,'Chi tiết SKU'!$A$2:$A$1253,$A9)/E9,0) -> 22 | L9: 0.13841 | M9: =IF(F9/E9>=$P$2,"CHẾT – hết hàng",IF(AND(H9>=$P$3,H9>=G9),"ĐẨY XUỐNG CH",IF(K9<$P$4,"PHỦ MỎNG","OK"))) -> ĐẨY XUỐNG CH | N9: Kho LTT còn 2,776 > tồn CH 2,329: lệnh điều chuyển bổ sung xuống CH trong tuần này, nhất là CH đang 0.
A10: CT002 | B10: CHĂM SÓC SẮC ĐẸP | C10: 10% | D10: Discount | E10: =COUNTIFS('Chi tiết SKU'!$A$2:$A$1253,$A10) -> 69 | F10: =COUNTIFS('Chi tiết SKU'!$A$2:$A$1253,$A10,'Chi tiết SKU'!$R$2:$R$1253,"<=0") -> 0 | G10: =SUMIFS('Chi tiết SKU'!$M$2:$M$1253,'Chi tiết SKU'!$A$2:$A$1253,$A10) -> 6221 | H10: =SUMIFS('Chi tiết SKU'!$N$2:$N$1253,'Chi tiết SKU'!$A$2:$A$1253,$A10) -> 709 | I10: =SUMIFS('Chi tiết SKU'!$O$2:$O$1253,'Chi tiết SKU'!$A$2:$A$1253,$A10) -> 620 | J10: =SUMIFS('Chi tiết SKU'!$T$2:$T$1253,'Chi tiết SKU'!$A$2:$A$1253,$A10) -> 1292830000 | K10: =IFERROR(SUMIFS('Chi tiết SKU'!$S$2:$S$1253,'Chi tiết SKU'!$A$2:$A$1253,$A10)/E10,0) -> 17.811594 | L10: 0.1 | M10: =IF(F10/E10>=$P$2,"CHẾT – hết hàng",IF(AND(H10>=$P$3,H10>=G10),"ĐẨY XUỐNG CH",IF(K10<$P$4,"PHỦ MỎNG","OK"))) -> OK | N10: Đủ hàng: tập trung trưng bày + kịch bản tư vấn, theo dõi sell-out tuần.
A11: CT057 | B11: CHĂM SÓC SỨC KHỎE | C11: Giảm ngay 200K khi mua Collagen 82X | D11: Discount | E11: =COUNTIFS('Chi tiết SKU'!$A$2:$A$1253,$A11) -> 5 | F11: =COUNTIFS('Chi tiết SKU'!$A$2:$A$1253,$A11,'Chi tiết SKU'!$R$2:$R$1253,"<=0") -> 0 | G11: =SUMIFS('Chi tiết SKU'!$M$2:$M$1253,'Chi tiết SKU'!$A$2:$A$1253,$A11) -> 558 | H11: =SUMIFS('Chi tiết SKU'!$N$2:$N$1253,'Chi tiết SKU'!$A$2:$A$1253,$A11) -> 0 | I11: =SUMIFS('Chi tiết SKU'!$O$2:$O$1253,'Chi tiết SKU'!$A$2:$A$1253,$A11) -> 6 | J11: =SUMIFS('Chi tiết SKU'!$T$2:$T$1253,'Chi tiết SKU'!$A$2:$A$1253,$A11) -> 1087733000 | K11: =IFERROR(SUMIFS('Chi tiết SKU'!$S$2:$S$1253,'Chi tiết SKU'!$A$2:$A$1253,$A11)/E11,0) -> 21.6 | L11: 0.08333 | M11: =IF(F11/E11>=$P$2,"CHẾT – hết hàng",IF(AND(H11>=$P$3,H11>=G11),"ĐẨY XUỐNG CH",IF(K11<$P$4,"PHỦ MỎNG","OK"))) -> OK | N11: Đủ hàng: tập trung trưng bày + kịch bản tư vấn, theo dõi sell-out tuần.
A12: CT004 | B12: NHÀ CỬA ĐỜI SỐNG | C12: Nước rửa bát 1250ml giá 188k->159K | D12: Discount | E12: =COUNTIFS('Chi tiết SKU'!$A$2:$A$1253,$A12) -> 7 | F12: =COUNTIFS('Chi tiết SKU'!$A$2:$A$1253,$A12,'Chi tiết SKU'!$R$2:$R$1253,"<=0") -> 0 | G12: =SUMIFS('Chi tiết SKU'!$M$2:$M$1253,'Chi tiết SKU'!$A$2:$A$1253,$A12) -> 2772 | H12: =SUMIFS('Chi tiết SKU'!$N$2:$N$1253,'Chi tiết SKU'!$A$2:$A$1253,$A12) -> 733 | I12: =SUMIFS('Chi tiết SKU'!$O$2:$O$1253,'Chi tiết SKU'!$A$2:$A$1253,$A12) -> 1425 | J12: =SUMIFS('Chi tiết SKU'!$T$2:$T$1253,'Chi tiết SKU'!$A$2:$A$1253,$A12) -> 950502000 | K12: =IFERROR(SUMIFS('Chi tiết SKU'!$S$2:$S$1253,'Chi tiết SKU'!$A$2:$A$1253,$A12)/E12,0) -> 22.428571 | L12: 0.15426 | M12: =IF(F12/E12>=$P$2,"CHẾT – hết hàng",IF(AND(H12>=$P$3,H12>=G12),"ĐẨY XUỐNG CH",IF(K12<$P$4,"PHỦ MỎNG","OK"))) -> OK | N12: Đủ hàng: tập trung trưng bày + kịch bản tư vấn, theo dõi sell-out tuần.
A13: CT007 | B13: NHÀ CỬA ĐỜI SỐNG | C13: Gia dụng KAI đồng giảm 10% | D13: Discount | E13: =COUNTIFS('Chi tiết SKU'!$A$2:$A$1253,$A13) -> 101 | F13: =COUNTIFS('Chi tiết SKU'!$A$2:$A$1253,$A13,'Chi tiết SKU'!$R$2:$R$1253,"<=0") -> 3 | G13: =SUMIFS('Chi tiết SKU'!$M$2:$M$1253,'Chi tiết SKU'!$A$2:$A$1253,$A13) -> 4557 | H13: =SUMIFS('Chi tiết SKU'!$N$2:$N$1253,'Chi tiết SKU'!$A$2:$A$1253,$A13) -> 6 | I13: =SUMIFS('Chi tiết SKU'!$O$2:$O$1253,'Chi tiết SKU'!$A$2:$A$1253,$A13) -> 385 | J13: =SUMIFS('Chi tiết SKU'!$T$2:$T$1253,'Chi tiết SKU'!$A$2:$A$1253,$A13) -> 915845000 | K13: =IFERROR(SUMIFS('Chi tiết SKU'!$S$2:$S$1253,'Chi tiết SKU'!$A$2:$A$1253,$A13)/E13,0) -> 10.415842 | L13: 0.1 | M13: =IF(F13/E13>=$P$2,"CHẾT – hết hàng",IF(AND(H13>=$P$3,H13>=G13),"ĐẨY XUỐNG CH",IF(K13<$P$4,"PHỦ MỎNG","OK"))) -> OK | N13: Long-tail nhiều SKU, phủ thấp: chọn top 20 SKU bán chạy làm đảo/kệ đầu; còn lại giữ kệ thường + tag giảm 10%.
A14: CT012 | B14: CHĂM SÓC SẮC ĐẸP | C14: Giảm ngay 20K khi mua trang điểm mắt Kissme | D14: Discount | E14: =COUNTIFS('Chi tiết SKU'!$A$2:$A$1253,$A14) -> 50 | F14: =COUNTIFS('Chi tiết SKU'!$A$2:$A$1253,$A14,'Chi tiết SKU'!$R$2:$R$1253,"<=0") -> 4 | G14: =SUMIFS('Chi tiết SKU'!$M$2:$M$1253,'Chi tiết SKU'!$A$2:$A$1253,$A14) -> 3200 | H14: =SUMIFS('Chi tiết SKU'!$N$2:$N$1253,'Chi tiết SKU'!$A$2:$A$1253,$A14) -> 338 | I14: =SUMIFS('Chi tiết SKU'!$O$2:$O$1253,'Chi tiết SKU'!$A$2:$A$1253,$A14) -> 123 | J14: =SUMIFS('Chi tiết SKU'!$T$2:$T$1253,'Chi tiết SKU'!$A$2:$A$1253,$A14) -> 899837000 | K14: =IFERROR(SUMIFS('Chi tiết SKU'!$S$2:$S$1253,'Chi tiết SKU'!$A$2:$A$1253,$A14)/E14,0) -> 15.78 | L14: 0.0772 | M14: =IF(F14/E14>=$P$2,"CHẾT – hết hàng",IF(AND(H14>=$P$3,H14>=G14),"ĐẨY XUỐNG CH",IF(K14<$P$4,"PHỦ MỎNG","OK"))) -> OK | N14: Đủ hàng: tập trung trưng bày + kịch bản tư vấn, theo dõi sell-out tuần.
A15: CT052 | B15: CHĂM SÓC SỨC KHỎE | C15: Giảm ngay 50K khi mua bổ gan Zeria | D15: Discount | E15: =COUNTIFS('Chi tiết SKU'!$A$2:$A$1253,$A15) -> 5 | F15: =COUNTIFS('Chi tiết SKU'!$A$2:$A$1253,$A15,'Chi tiết SKU'!$R$2:$R$1253,"<=0") -> 0 | G15: =SUMIFS('Chi tiết SKU'!$M$2:$M$1253,'Chi tiết SKU'!$A$2:$A$1253,$A15) -> 543 | H15: =SUMIFS('Chi tiết SKU'!$N$2:$N$1253,'Chi tiết SKU'!$A$2:$A$1253,$A15) -> 0 | I15: =SUMIFS('Chi tiết SKU'!$O$2:$O$1253,'Chi tiết SKU'!$A$2:$A$1253,$A15) -> 49 | J15: =SUMIFS('Chi tiết SKU'!$T$2:$T$1253,'Chi tiết SKU'!$A$2:$A$1253,$A15) -> 766293000 | K15: =IFERROR(SUMIFS('Chi tiết SKU'!$S$2:$S$1253,'Chi tiết SKU'!$A$2:$A$1253,$A15)/E15,0) -> 21 | L15: 0.03623 | M15: =IF(F15/E15>=$P$2,"CHẾT – hết hàng",IF(AND(H15>=$P$3,H15>=G15),"ĐẨY XUỐNG CH",IF(K15<$P$4,"PHỦ MỎNG","OK"))) -> OK | N15: Đủ hàng: tập trung trưng bày + kịch bản tư vấn, theo dõi sell-out tuần.
A16: CT016 | B16: BỈM | C16: Bỉm Merries mua 1 giảm 40K, mua từ 2 giảm 60k/bịch | D16: Mua càng nhiều giá càng rẻ | E16: =COUNTIFS('Chi tiết SKU'!$A$2:$A$1253,$A16) -> 9 | F16: =COUNTIFS('Chi tiết SKU'!$A$2:$A$1253,$A16,'Chi tiết SKU'!$R$2:$R$1253,"<=0") -> 0 | G16: =SUMIFS('Chi tiết SKU'!$M$2:$M$1253,'Chi tiết SKU'!$A$2:$A$1253,$A16) -> 1592 | H16: =SUMIFS('Chi tiết SKU'!$N$2:$N$1253,'Chi tiết SKU'!$A$2:$A$1253,$A16) -> 263 | I16: =SUMIFS('Chi tiết SKU'!$O$2:$O$1253,'Chi tiết SKU'!$A$2:$A$1253,$A16) -> 139 | J16: =SUMIFS('Chi tiết SKU'!$T$2:$T$1253,'Chi tiết SKU'!$A$2:$A$1253,$A16) -> 742400000 | K16: =IFERROR(SUMIFS('Chi tiết SKU'!$S$2:$S$1253,'Chi tiết SKU'!$A$2:$A$1253,$A16)/E16,0) -> 18.222222 | L16: 0.17143 | M16: =IF(F16/E16>=$P$2,"CHẾT – hết hàng",IF(AND(H16>=$P$3,H16>=G16),"ĐẨY XUỐNG CH",IF(K16<$P$4,"PHỦ MỎNG","OK"))) -> OK | N16: Đủ hàng: tập trung trưng bày + kịch bản tư vấn, theo dõi sell-out tuần.
... A20: CT051 | B20: CHĂM SÓC SỨC KHỎE | C20: Giảm ngay 50K khi mua Black Mores | D20: Discount | E20: =COUNTIFS('Chi tiết SKU'!$A$2:$A$1253,$A20) -> 7 | F20: =COUNTIFS('Chi tiết SKU'!$A$2:$A$1253,$A20,'Chi tiết SKU'!$R$2:$R$1253,"<=0") -> 0 | G20: =SUMIFS('Chi tiết SKU'!$M$2:$M$1253,'Chi tiết SKU'!$A$2:$A$1253,$A20) -> 506 | H20: =SUMIFS('Chi tiết SKU'!$N$2:$N$1253,'Chi tiết SKU'!$A$2:$A$1253,$A20) -> 67 | I20: =SUMIFS('Chi tiết SKU'!$O$2:$O$1253,'Chi tiết SKU'!$A$2:$A$1253,$A20) -> 38 | J20: =SUMIFS('Chi tiết SKU'!$T$2:$T$1253,'Chi tiết SKU'!$A$2:$A$1253,$A20) -> 486395000 | K20: =IFERROR(SUMIFS('Chi tiết SKU'!$S$2:$S$1253,'Chi tiết SKU'!$A$2:$A$1253,$A20)/E20,0) -> 19 | L20: 0.06061 | M20: =IF(F20/E20>=$P$2,"CHẾT – hết hàng",IF(AND(H20>=$P$3,H20>=G20),"ĐẨY XUỐNG CH",IF(K20<$P$4,"PHỦ MỎNG","OK"))) -> OK | N20: Đủ hàng: tập trung trưng bày + kịch bản tư vấn, theo dõi sell-out tuần.
A21: CT023 | B21: CHĂM SÓC SẮC ĐẸP | C21: Combo gội +xả tặng sữa tắm hương cam quýt hoặc hương trái cây hoặc dầu gội khô(101992 hoặc 101990 hoặc 102213) | D21: Combo | E21: =COUNTIFS('Chi tiết SKU'!$A$2:$A$1253,$A21) -> 11 | F21: =COUNTIFS('Chi tiết SKU'!$A$2:$A$1253,$A21,'Chi tiết SKU'!$R$2:$R$1253,"<=0") -> 0 | G21: =SUMIFS('Chi tiết SKU'!$M$2:$M$1253,'Chi tiết SKU'!$A$2:$A$1253,$A21) -> 1203 | H21: =SUMIFS('Chi tiết SKU'!$N$2:$N$1253,'Chi tiết SKU'!$A$2:$A$1253,$A21) -> 378 | I21: =SUMIFS('Chi tiết SKU'!$O$2:$O$1253,'Chi tiết SKU'!$A$2:$A$1253,$A21) -> 292 | J21: =SUMIFS('Chi tiết SKU'!$T$2:$T$1253,'Chi tiết SKU'!$A$2:$A$1253,$A21) -> 476285000 | K21: =IFERROR(SUMIFS('Chi tiết SKU'!$S$2:$S$1253,'Chi tiết SKU'!$A$2:$A$1253,$A21)/E21,0) -> 19.909091 | M21: =IF(F21/E21>=$P$2,"CHẾT – hết hàng",IF(AND(H21>=$P$3,H21>=G21),"ĐẨY XUỐNG CH",IF(K21<$P$4,"PHỦ MỎNG","OK"))) -> OK | N21: Xả cuối vụ: dồn hàng về CH bán tốt, bàn/thùng đồng giá ở lối vào; KPI sell-through ≥70% đến 31/10.
A22: CT025 | B22: CHĂM SÓC SẮC ĐẸP | C22: Giảm ngay 30K khi mua mỹ phẩm Cezanne | D22: Discount | E22: =COUNTIFS('Chi tiết SKU'!$A$2:$A$1253,$A22) -> 25 | F22: =COUNTIFS('Chi tiết SKU'!$A$2:$A$1253,$A22,'Chi tiết SKU'!$R$2:$R$1253,"<=0") -> 0 | G22: =SUMIFS('Chi tiết SKU'!$M$2:$M$1253,'Chi tiết SKU'!$A$2:$A$1253,$A22) -> 1674 | H22: =SUMIFS('Chi tiết SKU'!$N$2:$N$1253,'Chi tiết SKU'!$A$2:$A$1253,$A22) -> 60 | I22: =SUMIFS('Chi tiết SKU'!$O$2:$O$1253,'Chi tiết SKU'!$A$2:$A$1253,$A22) -> 121 | J22: =SUMIFS('Chi tiết SKU'!$T$2:$T$1253,'Chi tiết SKU'!$A$2:$A$1253,$A22) -> 453523000 | K22: =IFERROR(SUMIFS('Chi tiết SKU'!$S$2:$S$1253,'Chi tiết SKU'!$A$2:$A$1253,$A22)/E22,0) -> 19.28 | L22: 0.11538 | M22: =IF(F22/E22>=$P$2,"CHẾT – hết hàng",IF(AND(H22>=$P$3,H22>=G22),"ĐẨY XUỐNG CH",IF(K22<$P$4,"PHỦ MỎNG","OK"))) -> OK | N22: Đủ hàng: tập trung trưng bày + kịch bản tư vấn, theo dõi sell-out tuần.
A23: CT005 | B23: BÁNH NGỌT - TRÁNG MIỆNG | C23: Kem đồng giảm 8% | D23: Discount | E23: =COUNTIFS('Chi tiết SKU'!$A$2:$A$1253,$A23) -> 46 | F23: =COUNTIFS('Chi tiết SKU'!$A$2:$A$1253,$A23,'Chi tiết SKU'!$R$2:$R$1253,"<=0") -> 1 | G23: =SUMIFS('Chi tiết SKU'!$M$2:$M$1253,'Chi tiết SKU'!$A$2:$A$1253,$A23) -> 5562 | H23: =SUMIFS('Chi tiết SKU'!$N$2:$N$1253,'Chi tiết SKU'!$A$2:$A$1253,$A23) -> 0 | I23: =SUMIFS('Chi tiết SKU'!$O$2:$O$1253,'Chi tiết SKU'!$A$2:$A$1253,$A23) -> 0 | J23: =SUMIFS('Chi tiết SKU'!$T$2:$T$1253,'Chi tiết SKU'!$A$2:$A$1253,$A23) -> 341550000 | K23: =IFERROR(SUMIFS('Chi tiết SKU'!$S$2:$S$1253,'Chi tiết SKU'!$A$2:$A$1253,$A23)/E23,0) -> 7.5217391 | L23: 0.08 | M23: =IF(F23/E23>=$P$2,"CHẾT – hết hàng",IF(AND(H23>=$P$3,H23>=G23),"ĐẨY XUỐNG CH",IF(K23<$P$4,"PHỦ MỎNG","OK"))) -> PHỦ MỎNG | N23: Phủ mỏng: xác định CH bán được (top 8–10) và dồn hàng, tránh để 1–2 sp/CH không đủ trưng bày.
A24: CT031 | B24: THỰC PHẨM | C24: Mì chính 1kg giá 225K->209K | D24: Discount | E24: =COUNTIFS('Chi tiết SKU'!$A$2:$A$1253,$A24) -> 1 | F24: =COUNTIFS('Chi tiết SKU'!$A$2:$A$1253,$A24,'Chi tiết SKU'!$R$2:$R$1253,"<=0") -> 0 | G24: =SUMIFS('Chi tiết SKU'!$M$2:$M$1253,'Chi tiết SKU'!$A$2:$A$1253,$A24) -> 787 | H24: =SUMIFS('Chi tiết SKU'!$N$2:$N$1253,'Chi tiết SKU'!$A$2:$A$1253,$A24) -> 360 | I24: =SUMIFS('Chi tiết SKU'!$O$2:$O$1253,'Chi tiết SKU'!$A$2:$A$1253,$A24) -> 289 | J24: =SUMIFS('Chi tiết SKU'!$T$2:$T$1253,'Chi tiết SKU'!$A$2:$A$1253,$A24) -> 318360000 | K24: =IFERROR(SUMIFS('Chi tiết SKU'!$S$2:$S$1253,'Chi tiết SKU'!$A$2:$A$1253,$A24)/E24,0) -> 24 | L24: 0.07111 | M24: =IF(F24/E24>=$P$2,"CHẾT – hết hàng",IF(AND(H24>=$P$3,H24>=G24),"ĐẨY XUỐNG CH",IF(K24<$P$4,"PHỦ MỎNG","OK"))) -> OK | N24: Đủ hàng: tập trung trưng bày + kịch bản tư vấn, theo dõi sell-out tuần.
A25: CT018 | B25: HÀNG ĐÔNG LẠNH | C25: Thịt bò Sakura Beef mua 3 tặng 1, mua 5 tặng 2 (đồng thời tặng kèm 1 túi giữ nhiệt) | D25: Mua càng nhiều giá càng rẻ | E25: =COUNTIFS('Chi tiết SKU'!$A$2:$A$1253,$A25) -> 2 | F25: =COUNTIFS('Chi tiết SKU'!$A$2:$A$1253,$A25,'Chi tiết SKU'!$R$2:$R$1253,"<=0") -> 0 | G25: =SUMIFS('Chi tiết SKU'!$M$2:$M$1253,'Chi tiết SKU'!$A$2:$A$1253,$A25) -> 2457 | H25: =SUMIFS('Chi tiết SKU'!$N$2:$N$1253,'Chi tiết SKU'!$A$2:$A$1253,$A25) -> 0 | I25: =SUMIFS('Chi tiết SKU'!$O$2:$O$1253,'Chi tiết SKU'!$A$2:$A$1253,$A25) -> 0 | J25: =SUMIFS('Chi tiết SKU'!$T$2:$T$1253,'Chi tiết SKU'!$A$2:$A$1253,$A25) -> 289926000 | K25: =IFERROR(SUMIFS('Chi tiết SKU'!$S$2:$S$1253,'Chi tiết SKU'!$A$2:$A$1253,$A25)/E25,0) -> 15.5 | L25: 0.28571 | M25: =IF(F25/E25>=$P$2,"CHẾT – hết hàng",IF(AND(H25>=$P$3,H25>=G25),"ĐẨY XUỐNG CH",IF(K25<$P$4,"PHỦ MỎNG","OK"))) -> OK | N25: Đủ hàng: tập trung trưng bày + kịch bản tư vấn, theo dõi sell-out tuần.
A26: CT053 | B26: CHĂM SÓC SỨC KHỎE | C26: Collagen Alfe mua 1 giảm 10%, mua từ 3 giảm 20% | D26: Mua càng nhiều giá càng rẻ | E26: =COUNTIFS('Chi tiết SKU'!$A$2:$A$1253,$A26) -> 3 | F26: =COUNTIFS('Chi tiết SKU'!$A$2:$A$1253,$A26,'Chi tiết SKU'!$R$2:$R$1253,"<=0") -> 0 | G26: =SUMIFS('Chi tiết SKU'!$M$2:$M$1253,'Chi tiết SKU'!$A$2:$A$1253,$A26) -> 566 | H26: =SUMIFS('Chi tiết SKU'!$N$2:$N$1253,'Chi tiết SKU'!$A$2:$A$1253,$A26) -> 0 | I26: =SUMIFS('Chi tiết SKU'!$O$2:$O$1253,'Chi tiết SKU'!$A$2:$A$1253,$A26) -> 24 | J26: =SUMIFS('Chi tiết SKU'!$T$2:$T$1253,'Chi tiết SKU'!$A$2:$A$1253,$A26) -> 289394000 | K26: =IFERROR(SUMIFS('Chi tiết SKU'!$S$2:$S$1253,'Chi tiết SKU'!$A$2:$A$1253,$A26)/E26,0) -> 22.666667 | L26: 0.2 | M26: =IF(F26/E26>=$P$2,"CHẾT – hết hàng",IF(AND(H26>=$P$3,H26>=G26),"ĐẨY XUỐNG CH",IF(K26<$P$4,"PHỦ MỎNG","OK"))) -> OK | N26: Đủ hàng: tập trung trưng bày + kịch bản tư vấn, theo dõi sell-out tuần.
A27: CT011 | B27: THỰC PHẨM FRESH | C27: Phomai QBB giá 85K->75K | D27: Discount | E27: =COUNTIFS('Chi tiết SKU'!$A$2:$A$1253,$A27) -> 12 | F27: =COUNTIFS('Chi tiết SKU'!$A$2:$A$1253,$A27,'Chi tiết SKU'!$R$2:$R$1253,"<=0") -> 0 | G27: =SUMIFS('Chi tiết SKU'!$M$2:$M$1253,'Chi tiết SKU'!$A$2:$A$1253,$A27) -> 3709 | H27: =SUMIFS('Chi tiết SKU'!$N$2:$N$1253,'Chi tiết SKU'!$A$2:$A$1253,$A27) -> 0 | I27: =SUMIFS('Chi tiết SKU'!$O$2:$O$1253,'Chi tiết SKU'!$A$2:$A$1253,$A27) -> 0 | J27: =SUMIFS('Chi tiết SKU'!$T$2:$T$1253,'Chi tiết SKU'!$A$2:$A$1253,$A27) -> 278175000 | K27: =IFERROR(SUMIFS('Chi tiết SKU'!$S$2:$S$1253,'Chi tiết SKU'!$A$2:$A$1253,$A27)/E27,0) -> 16.083333 | L27: 0.11765 | M27: =IF(F27/E27>=$P$2,"CHẾT – hết hàng",IF(AND(H27>=$P$3,H27>=G27),"ĐẨY XUỐNG CH",IF(K27<$P$4,"PHỦ MỎNG","OK"))) -> OK | N27: Đủ hàng: tập trung trưng bày + kịch bản tư vấn, theo dõi sell-out tuần.
A28: CT020 | B28: CHĂM SÓC SẮC ĐẸP | C28: Combo Gội xả Hatomugi giá 330K chỉ còn 239K | D28: Combo | E28: =COUNTIFS('Chi tiết SKU'!$A$2:$A$1253,$A28) -> 2 | F28: =COUNTIFS('Chi tiết SKU'!$A$2:$A$1253,$A28,'Chi tiết SKU'!$R$2:$R$1253,"<=0") -> 0 | G28: =SUMIFS('Chi tiết SKU'!$M$2:$M$1253,'Chi tiết SKU'!$A$2:$A$1253,$A28) -> 478 | H28: =SUMIFS('Chi tiết SKU'!$N$2:$N$1253,'Chi tiết SKU'!$A$2:$A$1253,$A28) -> 1728 | I28: =SUMIFS('Chi tiết SKU'!$O$2:$O$1253,'Chi tiết SKU'!$A$2:$A$1253,$A28) -> 116 | J28: =SUMIFS('Chi tiết SKU'!$T$2:$T$1253,'Chi tiết SKU'!$A$2:$A$1253,$A28) -> 276318000 | K28: =IFERROR(SUMIFS('Chi tiết SKU'!$S$2:$S$1253,'Chi tiết SKU'!$A$2:$A$1253,$A28)/E28,0) -> 23 | L28: 0.27576 | M28: =IF(F28/E28>=$P$2,"CHẾT – hết hàng",IF(AND(H28>=$P$3,H28>=G28),"ĐẨY XUỐNG CH",IF(K28<$P$4,"PHỦ MỎNG","OK"))) -> ĐẨY XUỐNG CH | N28: Xả cuối vụ: dồn hàng về CH bán tốt, bàn/thùng đồng giá ở lối vào; KPI sell-through ≥70% đến 31/10.
A29: CT036 | B29: CHĂM SÓC SẮC ĐẸP | C29: Thuốc nhộm Hoyu giá 285k->259k | D29: Discount | E29: =COUNTIFS('Chi tiết SKU'!$A$2:$A$1253,$A29) -> 6 | F29: =COUNTIFS('Chi tiết SKU'!$A$2:$A$1253,$A29,'Chi tiết SKU'!$R$2:$R$1253,"<=0") -> 0 | G29: =SUMIFS('Chi tiết SKU'!$M$2:$M$1253,'Chi tiết SKU'!$A$2:$A$1253,$A29) -> 892 | H29: =SUMIFS('Chi tiết SKU'!$N$2:$N$1253,'Chi tiết SKU'!$A$2:$A$1253,$A29) -> 22 | I29: =SUMIFS('Chi tiết SKU'!$O$2:$O$1253,'Chi tiết SKU'!$A$2:$A$1253,$A29) -> 106 | J29: =SUMIFS('Chi tiết SKU'!$T$2:$T$1253,'Chi tiết SKU'!$A$2:$A$1253,$A29) -> 272468000 | K29: =IFERROR(SUMIFS('Chi tiết SKU'!$S$2:$S$1253,'Chi tiết SKU'!$A$2:$A$1253,$A29)/E29,0) -> 22.5 | L29: 0.09123 | M29: =IF(F29/E29>=$P$2,"CHẾT – hết hàng",IF(AND(H29>=$P$3,H29>=G29),"ĐẨY XUỐNG CH",IF(K29<$P$4,"PHỦ MỎNG","OK"))) -> OK | N29: Đủ hàng: tập trung trưng bày + kịch bản tư vấn, theo dõi sell-out tuần.
A30: CT029 | B30: THỰC PHẨM | C30: Ngũ cốc Calbee giá 205K->169K | D30: Discount | E30: =COUNTIFS('Chi tiết SKU'!$A$2:$A$1253,$A30) -> 4 | F30: =COUNTIFS('Chi tiết SKU'!$A$2:$A$1253,$A30,'Chi tiết SKU'!$R$2:$R$1253,"<=0") -> 0 | G30: =SUMIFS('Chi tiết SKU'!$M$2:$M$1253,'Chi tiết SKU'!$A$2:$A$1253,$A30) -> 994 | H30: =SUMIFS('Chi tiết SKU'!$N$2:$N$1253,'Chi tiết SKU'!$A$2:$A$1253,$A30) -> 0 | I30: =SUMIFS('Chi tiết SKU'!$O$2:$O$1253,'Chi tiết SKU'!$A$2:$A$1253,$A30) -> 262 | J30: =SUMIFS('Chi tiết SKU'!$T$2:$T$1253,'Chi tiết SKU'!$A$2:$A$1253,$A30) -> 269640000 | K30: =IFERROR(SUMIFS('Chi tiết SKU'!$S$2:$S$1253,'Chi tiết SKU'!$A$2:$A$1253,$A30)/E30,0) -> 18.25 | L30: 0.18462 | M30: =IF(F30/E30>=$P$2,"CHẾT – hết hàng",IF(AND(H30>=$P$3,H30>=G30),"ĐẨY XUỐNG CH",IF(K30<$P$4,"PHỦ MỎNG","OK"))) -> OK | N30: Đủ hàng: tập trung trưng bày + kịch bản tư vấn, theo dõi sell-out tuần.
A31: CT071 | B31: CHĂM SÓC SẮC ĐẸP | C31: Giảm ngay 100k khi mua mĩ phẩm cao cấp ATTENIR | D31: Discount | E31: =COUNTIFS('Chi tiết SKU'!$A$2:$A$1253,$A31) -> 9 | F31: =COUNTIFS('Chi tiết SKU'!$A$2:$A$1253,$A31,'Chi tiết SKU'!$R$2:$R$1253,"<=0") -> 0 | G31: =SUMIFS('Chi tiết SKU'!$M$2:$M$1253,'Chi tiết SKU'!$A$2:$A$1253,$A31) -> 324 | H31: =SUMIFS('Chi tiết SKU'!$N$2:$N$1253,'Chi tiết SKU'!$A$2:$A$1253,$A31) -> 0 | I31: =SUMIFS('Chi tiết SKU'!$O$2:$O$1253,'Chi tiết SKU'!$A$2:$A$1253,$A31) -> 0 | J31: =SUMIFS('Chi tiết SKU'!$T$2:$T$1253,'Chi tiết SKU'!$A$2:$A$1253,$A31) -> 259276000 | K31: =IFERROR(SUMIFS('Chi tiết SKU'!$S$2:$S$1253,'Chi tiết SKU'!$A$2:$A$1253,$A31)/E31,0) -> 9.7777778 | L31: 0.1497 | M31: =IF(F31/E31>=$P$2,"CHẾT – hết hàng",IF(AND(H31>=$P$3,H31>=G31),"ĐẨY XUỐNG CH",IF(K31<$P$4,"PHỦ MỎNG","OK"))) -> OK | N31: Đủ hàng: tập trung trưng bày + kịch bản tư vấn, theo dõi sell-out tuần.
A32: CT015 | B32: CHĂM SÓC HÀNG NGÀY | C32: Giảm ngay 15K khi mua băng vệ sinh Kleannara | D32: Discount | E32: =COUNTIFS('Chi tiết SKU'!$A$2:$A$1253,$A32) -> 14 | F32: =COUNTIFS('Chi tiết SKU'!$A$2:$A$1253,$A32,'Chi tiết SKU'!$R$2:$R$1253,"<=0") -> 0 | G32: =SUMIFS('Chi tiết SKU'!$M$2:$M$1253,'Chi tiết SKU'!$A$2:$A$1253,$A32) -> 1780 | H32: =SUMIFS('Chi tiết SKU'!$N$2:$N$1253,'Chi tiết SKU'!$A$2:$A$1253,$A32) -> 563 | I32: =SUMIFS('Chi tiết SKU'!$O$2:$O$1253,'Chi tiết SKU'!$A$2:$A$1253,$A32) -> 283 | J32: =SUMIFS('Chi tiết SKU'!$T$2:$T$1253,'Chi tiết SKU'!$A$2:$A$1253,$A32) -> 258196000 | K32: =IFERROR(SUMIFS('Chi tiết SKU'!$S$2:$S$1253,'Chi tiết SKU'!$A$2:$A$1253,$A32)/E32,0) -> 18.857143 | L32: 0.136645 | M32: =IF(F32/E32>=$P$2,"CHẾT – hết hàng",IF(AND(H32>=$P$3,H32>=G32),"ĐẨY XUỐNG CH",IF(K32<$P$4,"PHỦ MỎNG","OK"))) -> OK | N32: Đủ hàng: tập trung trưng bày + kịch bản tư vấn, theo dõi sell-out tuần.
A33: CT008 | B33: CHĂM SÓC HÀNG NGÀY | C33: KĐR White&White, muối mua 3 tặng 1 | D33: Combo | E33: =COUNTIFS('Chi tiết SKU'!$A$2:$A$1253,$A33) -> 2 | F33: =COUNTIFS('Chi tiết SKU'!$A$2:$A$1253,$A33,'Chi tiết SKU'!$R$2:$R$1253,"<=0") -> 0 | G33: =SUMIFS('Chi tiết SKU'!$M$2:$M$1253,'Chi tiết SKU'!$A$2:$A$1253,$A33) -> 2714 | H33: =SUMIFS('Chi tiết SKU'!$N$2:$N$1253,'Chi tiết SKU'!$A$2:$A$1253,$A33) -> 638 | I33: =SUMIFS('Chi tiết SKU'!$O$2:$O$1253,'Chi tiết SKU'!$A$2:$A$1253,$A33) -> 1077 | J33: =SUMIFS('Chi tiết SKU'!$T$2:$T$1253,'Chi tiết SKU'!$A$2:$A$1253,$A33) -> 250320000 | K33: =IFERROR(SUMIFS('Chi tiết SKU'!$S$2:$S$1253,'Chi tiết SKU'!$A$2:$A$1253,$A33)/E33,0) -> 23 | L33: 0.25 | M33: =IF(F33/E33>=$P$2,"CHẾT – hết hàng",IF(AND(H33>=$P$3,H33>=G33),"ĐẨY XUỐNG CH",IF(K33<$P$4,"PHỦ MỎNG","OK"))) -> OK | N33: Đủ hàng: tập trung trưng bày + kịch bản tư vấn, theo dõi sell-out tuần.
... A68: CT046 | B68: ĐỒ UỐNG | C68: Trà Oolong, trà sữa 1.5L giá chỉ còn 69K | D68: Discount | E68: =COUNTIFS('Chi tiết SKU'!$A$2:$A$1253,$A68) -> 2 | F68: =COUNTIFS('Chi tiết SKU'!$A$2:$A$1253,$A68,'Chi tiết SKU'!$R$2:$R$1253,"<=0") -> 0 | G68: =SUMIFS('Chi tiết SKU'!$M$2:$M$1253,'Chi tiết SKU'!$A$2:$A$1253,$A68) -> 601 | H68: =SUMIFS('Chi tiết SKU'!$N$2:$N$1253,'Chi tiết SKU'!$A$2:$A$1253,$A68) -> 0 | I68: =SUMIFS('Chi tiết SKU'!$O$2:$O$1253,'Chi tiết SKU'!$A$2:$A$1253,$A68) -> 130 | J68: =SUMIFS('Chi tiết SKU'!$T$2:$T$1253,'Chi tiết SKU'!$A$2:$A$1253,$A68) -> 52283000 | K68: =IFERROR(SUMIFS('Chi tiết SKU'!$S$2:$S$1253,'Chi tiết SKU'!$A$2:$A$1253,$A68)/E68,0) -> 21 | L68: 0.22462 | M68: =IF(F68/E68>=$P$2,"CHẾT – hết hàng",IF(AND(H68>=$P$3,H68>=G68),"ĐẨY XUỐNG CH",IF(K68<$P$4,"PHỦ MỎNG","OK"))) -> OK | N68: Đủ hàng: tập trung trưng bày + kịch bản tư vấn, theo dõi sell-out tuần.
A69: CT075 | B69: ĐỒ UỐNG | C69: Trà lá ổi nguyên chất 100% 200K->190K | D69: Discount | E69: =COUNTIFS('Chi tiết SKU'!$A$2:$A$1253,$A69) -> 1 | F69: =COUNTIFS('Chi tiết SKU'!$A$2:$A$1253,$A69,'Chi tiết SKU'!$R$2:$R$1253,"<=0") -> 0 | G69: =SUMIFS('Chi tiết SKU'!$M$2:$M$1253,'Chi tiết SKU'!$A$2:$A$1253,$A69) -> 234 | H69: =SUMIFS('Chi tiết SKU'!$N$2:$N$1253,'Chi tiết SKU'!$A$2:$A$1253,$A69) -> 0 | I69: =SUMIFS('Chi tiết SKU'!$O$2:$O$1253,'Chi tiết SKU'!$A$2:$A$1253,$A69) -> 24 | J69: =SUMIFS('Chi tiết SKU'!$T$2:$T$1253,'Chi tiết SKU'!$A$2:$A$1253,$A69) -> 52200000 | K69: =IFERROR(SUMIFS('Chi tiết SKU'!$S$2:$S$1253,'Chi tiết SKU'!$A$2:$A$1253,$A69)/E69,0) -> 23 | M69: =IF(F69/E69>=$P$2,"CHẾT – hết hàng",IF(AND(H69>=$P$3,H69>=G69),"ĐẨY XUỐNG CH",IF(K69<$P$4,"PHỦ MỎNG","OK"))) -> OK | N69: Đủ hàng: tập trung trưng bày + kịch bản tư vấn, theo dõi sell-out tuần.
A70: CT042 | B70: ĐỒ CHO MẸ BÉ | C70: Bánh ăn dặm beanstalk giá 69K->59K | D70: Discount | E70: =COUNTIFS('Chi tiết SKU'!$A$2:$A$1253,$A70) -> 6 | F70: =COUNTIFS('Chi tiết SKU'!$A$2:$A$1253,$A70,'Chi tiết SKU'!$R$2:$R$1253,"<=0") -> 0 | G70: =SUMIFS('Chi tiết SKU'!$M$2:$M$1253,'Chi tiết SKU'!$A$2:$A$1253,$A70) -> 775 | H70: =SUMIFS('Chi tiết SKU'!$N$2:$N$1253,'Chi tiết SKU'!$A$2:$A$1253,$A70) -> 0 | I70: =SUMIFS('Chi tiết SKU'!$O$2:$O$1253,'Chi tiết SKU'!$A$2:$A$1253,$A70) -> 70 | J70: =SUMIFS('Chi tiết SKU'!$T$2:$T$1253,'Chi tiết SKU'!$A$2:$A$1253,$A70) -> 49855000 | K70: =IFERROR(SUMIFS('Chi tiết SKU'!$S$2:$S$1253,'Chi tiết SKU'!$A$2:$A$1253,$A70)/E70,0) -> 18.5 | L70: 0.14493 | M70: =IF(F70/E70>=$P$2,"CHẾT – hết hàng",IF(AND(H70>=$P$3,H70>=G70),"ĐẨY XUỐNG CH",IF(K70<$P$4,"PHỦ MỎNG","OK"))) -> OK | N70: Đủ hàng: tập trung trưng bày + kịch bản tư vấn, theo dõi sell-out tuần.
A71: CT077 | B71: ĐỒ UỐNG | C71: Trà diếp cá túi lọc 200K->190K | D71: Discount | E71: =COUNTIFS('Chi tiết SKU'!$A$2:$A$1253,$A71) -> 1 | F71: =COUNTIFS('Chi tiết SKU'!$A$2:$A$1253,$A71,'Chi tiết SKU'!$R$2:$R$1253,"<=0") -> 0 | G71: =SUMIFS('Chi tiết SKU'!$M$2:$M$1253,'Chi tiết SKU'!$A$2:$A$1253,$A71) -> 222 | H71: =SUMIFS('Chi tiết SKU'!$N$2:$N$1253,'Chi tiết SKU'!$A$2:$A$1253,$A71) -> 0 | I71: =SUMIFS('Chi tiết SKU'!$O$2:$O$1253,'Chi tiết SKU'!$A$2:$A$1253,$A71) -> 24 | J71: =SUMIFS('Chi tiết SKU'!$T$2:$T$1253,'Chi tiết SKU'!$A$2:$A$1253,$A71) -> 49800000 | K71: =IFERROR(SUMIFS('Chi tiết SKU'!$S$2:$S$1253,'Chi tiết SKU'!$A$2:$A$1253,$A71)/E71,0) -> 22 | M71: =IF(F71/E71>=$P$2,"CHẾT – hết hàng",IF(AND(H71>=$P$3,H71>=G71),"ĐẨY XUỐNG CH",IF(K71<$P$4,"PHỦ MỎNG","OK"))) -> OK | N71: Đủ hàng: tập trung trưng bày + kịch bản tư vấn, theo dõi sell-out tuần.
A72: CT073 | B72: NHÀ CỬA ĐỜI SỐNG | C72: Nồi nấu đa năng SKK đồng giá 150K | D72: Discount | E72: =COUNTIFS('Chi tiết SKU'!$A$2:$A$1253,$A72) -> 10 | F72: =COUNTIFS('Chi tiết SKU'!$A$2:$A$1253,$A72,'Chi tiết SKU'!$R$2:$R$1253,"<=0") -> 0 | G72: =SUMIFS('Chi tiết SKU'!$M$2:$M$1253,'Chi tiết SKU'!$A$2:$A$1253,$A72) -> 301 | H72: =SUMIFS('Chi tiết SKU'!$N$2:$N$1253,'Chi tiết SKU'!$A$2:$A$1253,$A72) -> 0 | I72: =SUMIFS('Chi tiết SKU'!$O$2:$O$1253,'Chi tiết SKU'!$A$2:$A$1253,$A72) -> 0 | J72: =SUMIFS('Chi tiết SKU'!$T$2:$T$1253,'Chi tiết SKU'!$A$2:$A$1253,$A72) -> 45399000 | K72: =IFERROR(SUMIFS('Chi tiết SKU'!$S$2:$S$1253,'Chi tiết SKU'!$A$2:$A$1253,$A72)/E72,0) -> 6.7 | L72: 0.79638 | M72: =IF(F72/E72>=$P$2,"CHẾT – hết hàng",IF(AND(H72>=$P$3,H72>=G72),"ĐẨY XUỐNG CH",IF(K72<$P$4,"PHỦ MỎNG","OK"))) -> PHỦ MỎNG | N72: Phủ mỏng: xác định CH bán được (top 8–10) và dồn hàng, tránh để 1–2 sp/CH không đủ trưng bày.
A73: CT027 | B73: ĐỒ CHO MẸ BÉ | C73: Giấy ướt mua 3 tặng 1 | D73: Combo | E73: =COUNTIFS('Chi tiết SKU'!$A$2:$A$1253,$A73) -> 1 | F73: =COUNTIFS('Chi tiết SKU'!$A$2:$A$1253,$A73,'Chi tiết SKU'!$R$2:$R$1253,"<=0") -> 0 | G73: =SUMIFS('Chi tiết SKU'!$M$2:$M$1253,'Chi tiết SKU'!$A$2:$A$1253,$A73) -> 1219 | H73: =SUMIFS('Chi tiết SKU'!$N$2:$N$1253,'Chi tiết SKU'!$A$2:$A$1253,$A73) -> 306 | I73: =SUMIFS('Chi tiết SKU'!$O$2:$O$1253,'Chi tiết SKU'!$A$2:$A$1253,$A73) -> 100 | J73: =SUMIFS('Chi tiết SKU'!$T$2:$T$1253,'Chi tiết SKU'!$A$2:$A$1253,$A73) -> 43264000 | K73: =IFERROR(SUMIFS('Chi tiết SKU'!$S$2:$S$1253,'Chi tiết SKU'!$A$2:$A$1253,$A73)/E73,0) -> 22 | L73: 0.25 | M73: =IF(F73/E73>=$P$2,"CHẾT – hết hàng",IF(AND(H73>=$P$3,H73>=G73),"ĐẨY XUỐNG CH",IF(K73<$P$4,"PHỦ MỎNG","OK"))) -> OK | N73: Đủ hàng: tập trung trưng bày + kịch bản tư vấn, theo dõi sell-out tuần.
A74: CT033 | B74: ĐỒ UỐNG | C74: Coca nắp vặn 300ml mua từ 3 giá 39K->32K | D74: Combo | E74: =COUNTIFS('Chi tiết SKU'!$A$2:$A$1253,$A74) -> 1 | F74: =COUNTIFS('Chi tiết SKU'!$A$2:$A$1253,$A74,'Chi tiết SKU'!$R$2:$R$1253,"<=0") -> 0 | G74: =SUMIFS('Chi tiết SKU'!$M$2:$M$1253,'Chi tiết SKU'!$A$2:$A$1253,$A74) -> 1179 | H74: =SUMIFS('Chi tiết SKU'!$N$2:$N$1253,'Chi tiết SKU'!$A$2:$A$1253,$A74) -> 0 | I74: =SUMIFS('Chi tiết SKU'!$O$2:$O$1253,'Chi tiết SKU'!$A$2:$A$1253,$A74) -> 162 | J74: =SUMIFS('Chi tiết SKU'!$T$2:$T$1253,'Chi tiết SKU'!$A$2:$A$1253,$A74) -> 43168000 | K74: =IFERROR(SUMIFS('Chi tiết SKU'!$S$2:$S$1253,'Chi tiết SKU'!$A$2:$A$1253,$A74)/E74,0) -> 23 | L74: 0.17949 | M74: =IF(F74/E74>=$P$2,"CHẾT – hết hàng",IF(AND(H74>=$P$3,H74>=G74),"ĐẨY XUỐNG CH",IF(K74<$P$4,"PHỦ MỎNG","OK"))) -> OK | N74: Đủ hàng: tập trung trưng bày + kịch bản tư vấn, theo dõi sell-out tuần.
A75: CT050 | B75: CHĂM SÓC SẮC ĐẸP | C75: Bông tẩy trang Unicharm mua 2 tặng 1 | D75: Combo | E75: =COUNTIFS('Chi tiết SKU'!$A$2:$A$1253,$A75) -> 1 | F75: =COUNTIFS('Chi tiết SKU'!$A$2:$A$1253,$A75,'Chi tiết SKU'!$R$2:$R$1253,"<=0") -> 0 | G75: =SUMIFS('Chi tiết SKU'!$M$2:$M$1253,'Chi tiết SKU'!$A$2:$A$1253,$A75) -> 478 | H75: =SUMIFS('Chi tiết SKU'!$N$2:$N$1253,'Chi tiết SKU'!$A$2:$A$1253,$A75) -> 0 | I75: =SUMIFS('Chi tiết SKU'!$O$2:$O$1253,'Chi tiết SKU'!$A$2:$A$1253,$A75) -> 121 | J75: =SUMIFS('Chi tiết SKU'!$T$2:$T$1253,'Chi tiết SKU'!$A$2:$A$1253,$A75) -> 42273000 | K75: =IFERROR(SUMIFS('Chi tiết SKU'!$S$2:$S$1253,'Chi tiết SKU'!$A$2:$A$1253,$A75)/E75,0) -> 21 | L75: 0.33333 | M75: =IF(F75/E75>=$P$2,"CHẾT – hết hàng",IF(AND(H75>=$P$3,H75>=G75),"ĐẨY XUỐNG CH",IF(K75<$P$4,"PHỦ MỎNG","OK"))) -> OK | N75: Đủ hàng: tập trung trưng bày + kịch bản tư vấn, theo dõi sell-out tuần.
A76: CT080 | B76: CHĂM SÓC SỨC KHỎE | C76: Trà giảm mỡ bụng Genpi 220K->210K | D76: Discount | E76: =COUNTIFS('Chi tiết SKU'!$A$2:$A$1253,$A76) -> 1 | F76: =COUNTIFS('Chi tiết SKU'!$A$2:$A$1253,$A76,'Chi tiết SKU'!$R$2:$R$1253,"<=0") -> 0 | G76: =SUMIFS('Chi tiết SKU'!$M$2:$M$1253,'Chi tiết SKU'!$A$2:$A$1253,$A76) -> 131 | H76: =SUMIFS('Chi tiết SKU'!$N$2:$N$1253,'Chi tiết SKU'!$A$2:$A$1253,$A76) -> 0 | I76: =SUMIFS('Chi tiết SKU'!$O$2:$O$1253,'Chi tiết SKU'!$A$2:$A$1253,$A76) -> 38 | J76: =SUMIFS('Chi tiết SKU'!$T$2:$T$1253,'Chi tiết SKU'!$A$2:$A$1253,$A76) -> 40920000 | K76: =IFERROR(SUMIFS('Chi tiết SKU'!$S$2:$S$1253,'Chi tiết SKU'!$A$2:$A$1253,$A76)/E76,0) -> 23 | M76: =IF(F76/E76>=$P$2,"CHẾT – hết hàng",IF(AND(H76>=$P$3,H76>=G76),"ĐẨY XUỐNG CH",IF(K76<$P$4,"PHỦ MỎNG","OK"))) -> OK | N76: Đủ hàng: tập trung trưng bày + kịch bản tư vấn, theo dõi sell-out tuần.
A77: CT032 | B77: ĐỒ CHO MẸ BÉ | C77: Kem đánh răng KAO cho bé được tặng ngay 1 bàn chải cho UFC cho bé (174509) trị giá 40K | D77: Mua hàng tặng hàng | E77: =COUNTIFS('Chi tiết SKU'!$A$2:$A$1253,$A77) -> 4 | F77: =COUNTIFS('Chi tiết SKU'!$A$2:$A$1253,$A77,'Chi tiết SKU'!$R$2:$R$1253,"<=0") -> 0 | G77: =SUMIFS('Chi tiết SKU'!$M$2:$M$1253,'Chi tiết SKU'!$A$2:$A$1253,$A77) -> 573 | H77: =SUMIFS('Chi tiết SKU'!$N$2:$N$1253,'Chi tiết SKU'!$A$2:$A$1253,$A77) -> 770 | I77: =SUMIFS('Chi tiết SKU'!$O$2:$O$1253,'Chi tiết SKU'!$A$2:$A$1253,$A77) -> 107 | J77: =SUMIFS('Chi tiết SKU'!$T$2:$T$1253,'Chi tiết SKU'!$A$2:$A$1253,$A77) -> 37810000 | K77: =IFERROR(SUMIFS('Chi tiết SKU'!$S$2:$S$1253,'Chi tiết SKU'!$A$2:$A$1253,$A77)/E77,0) -> 17.75 | L77: 0.36036 | M77: =IF(F77/E77>=$P$2,"CHẾT – hết hàng",IF(AND(H77>=$P$3,H77>=G77),"ĐẨY XUỐNG CH",IF(K77<$P$4,"PHỦ MỎNG","OK"))) -> ĐẨY XUỐNG CH | N77: Kho LTT còn 770 > tồn CH 573: lệnh điều chuyển bổ sung xuống CH trong tuần này, nhất là CH đang 0.
...

Sheet Cần điều chuyển
A1: SKU KM CÓ HÀNG Ở KHO LTT NHƯNG CÓ CH ĐANG = 0 (đã loại giày & gia dụng KAI/KAIYO long-tail; loại SKK Vũ Phạm Hàm vì 0 tồn toàn bộ)
A3: Mã CT | B3: Ngành hàng | C3: Item | D3: Tên SP | E3: Nội dung CTKM | F3: Kho LTT | G3: Tồn CH | H3: Số CH = 0 | I3: Gợi ý cấp/CH thiếu | J3: Các CH đang = 0
A4: CT001 | B4: THỜI TRANG | C4: 142030 | D4: NISHIMATSUYA- Áo Khoác Trẻ em Nhật Bản | E4: Thời trang Nishimatsuya mùa đông giảm ngay 20% | F4: 337 | G4: 86 | H4: 17 | I4: =MIN(ROUNDUP(G4/MAX(1,24-H4),0),ROUNDDOWN(F4/H4,0)) -> 13 | J4: CVS 108-110 Linh Lang, Store JP Mandarin C1, Store JP Thái Hà, Store JP Trần Đăng Ninh, Store JP Nguyễn Du, Store JP Hàng Bông, Store JP Văn Phú, Store JP Hàm Nghi, Store JP Ngoại Giao Đoàn, SKK Trần Duy Hưng, Store JP Nguyễn Văn Lộc, Store JP Ecohome 3, SKK Vinhome Green Bay, SKK Xuân La, SKK Sài Đồng, SKK Bạch Mai, CVS 34 Vũ Phạm Hàm
A5: CT001 | B5: THỜI TRANG | C5: 142447 | D5: NISHIMATSUYA- Áo Len Áo Nỉ Nhật Bản | E5: Thời trang Nishimatsuya mùa đông giảm ngay 20% | F5: 5329 | G5: 1987 | H5: 14 | I5: =MIN(ROUNDUP(G5/MAX(1,24-H5),0),ROUNDDOWN(F5/H5,0)) -> 199 | J5: CVS 108-110 Linh Lang, Store JP Mandarin C1, Store JP Hàng Bông, Store JP Văn Phú, Store JP Hàm Nghi, Store JP Nguyễn Tuân, SKK Trần Duy Hưng, Store JP Ecohome 3, SKK Vinhome Green Bay, SKK Xuân La, SKK Nguyễn Khuyến, SKK Bạch Mai, SKK Bắc Ninh, CVS 34 Vũ Phạm Hàm
A6: CT024 | B6: CHĂM SÓC HÀNG NGÀY | C6: 30116 | D6: ELIS- BVS dạng quần size M-L màu da (2c) | E6: Mua băng vệ sinh ELLEAIR hằng ngày, ban đêm tặng ngay 1 băng vệ sinh quần (30116, 30115) trị giá 50K | F6: 10 | G6: 146 | H6: 13 | I6: =MIN(ROUNDUP(G6/MAX(1,24-H6),0),ROUNDDOWN(F6/H6,0)) -> 0 | J6: CVS 108-110 Linh Lang, Store JP Nguyễn Du, Store JP Hàng Bông, Store JP Nguyễn Tuân, Store JP Ngoại Giao Đoàn, Store JP Nguyễn Văn Lộc, Store JP T6 Time City, Store JP Ecohome 3, SKK Vinhome Green Bay, SKK Xuân La, SKK Sài Đồng, SKK Bắc Ninh, CVS 34 Vũ Phạm Hàm
A7: CT001 | B7: THỜI TRANG | C7: 142035 | D7: NISHIMATSUYA- Bộ Quần Áo Trẻ em Nhật Bản (Set rời) | E7: Thời trang Nishimatsuya mùa đông giảm ngay 20% | F7: 232 | G7: 453 | H7: 12 | I7: =MIN(ROUNDUP(G7/MAX(1,24-H7),0),ROUNDDOWN(F7/H7,0)) -> 19 | J7: CVS 108-110 Linh Lang, Store JP Linh Đàm, Store JP Thái Hà, Store JP Trần Đăng Ninh, Store JP Hàng Bông, Store JP Hàm Nghi, SKK Trần Duy Hưng, Store JP Ecohome 3, SKK Vinhome Green Bay, SKK Xuân La, SKK Bạch Mai, CVS 34 Vũ Phạm Hàm
A8: CT002 | B8: CHĂM SÓC SẮC ĐẸP | C8: 102436 | D8: UNO- Sữa rửa mặt tạo bọt sạch nhờn 130g | E8: 10% | F8: 34 | G8: 36 | H8: 11 | I8: =MIN(ROUNDUP(G8/MAX(1,24-H8),0),ROUNDDOWN(F8/H8,0)) -> 3 | J8: Store JP Linh Đàm, Store JP Văn Phú, Store JP Nguyễn Tuân, Store JP Đỗ Quang, Store JP Ngoại Giao Đoàn, SKK Trần Duy Hưng, Store JP T6 Time City, Store JP Ecohome 3, SKK Vinhome Green Bay, SKK Bắc Ninh, CVS 34 Vũ Phạm Hàm
A9: CT003 | B9: THỜI TRANG | C9: 143021 | D9: NISHIMATSUYA- Quần đùi cho trẻ em gái | E9: Thời trang Nishimatsuya mùa hè xả hàng cuối vụ đồng giá chỉ còn 19K | F9: 10 | G9: 270 | H9: 11 | I9: =MIN(ROUNDUP(G9/MAX(1,24-H9),0),ROUNDDOWN(F9/H9,0)) -> 0 | J9: CVS 108-110 Linh Lang, Store JP Thái Hà, Store JP Văn Phú, Store JP Nguyễn Tuân, Store JP Ngoại Giao Đoàn, SKK Trần Duy Hưng, SKK Vinhome Green Bay, SKK Xuân La, SKK Nguyễn Khuyến, SKK Bạch Mai, CVS 34 Vũ Phạm Hàm
A10: CT003 | B10: THỜI TRANG | C10: 143018 | D10: NISHIMATSUYA- Váy liền cho trẻ em gái | E10: Thời trang Nishimatsuya mùa hè xả hàng cuối vụ đồng giá chỉ còn 19K | F10: 1803 | G10: 517 | H10: 10 | I10: =MIN(ROUNDUP(G10/MAX(1,24-H10),0),ROUNDDOWN(F10/H10,0)) -> 37 | J10: CVS 108-110 Linh Lang, Store JP Mandarin C1, Store JP Nguyễn Tuân, Store JP Ngoại Giao Đoàn, SKK Trần Duy Hưng, SKK Vinhome Green Bay, SKK Xuân La, SKK Nguyễn Khuyến, SKK Bạch Mai, CVS 34 Vũ Phạm Hàm
A11: CT001 | B11: THỜI TRANG | C11: 142031 | D11: NISHIMATSUYA- Áo Len Áo Nỉ Nhật Bản | E11: Thời trang Nishimatsuya mùa đông giảm ngay 20% | F11: 4899 | G11: 2975 | H11: 9 | I11: =MIN(ROUNDUP(G11/MAX(1,24-H11),0),ROUNDDOWN(F11/H11,0)) -> 199 | J11: CVS 108-110 Linh Lang, Store JP Thái Hà, Store JP Nguyễn Du, Store JP Ngoại Giao Đoàn, SKK Trần Duy Hưng, Store JP Ecohome 3, SKK Vinhome Green Bay, SKK Xuân La, CVS 34 Vũ Phạm Hàm
A12: CT024 | B12: CHĂM SÓC HÀNG NGÀY | C12: 30115 | D12: ELIS- BVS dạng quần size M-L màu đen (2c) | E12: Mua băng vệ sinh ELLEAIR hằng ngày, ban đêm tặng ngay 1 băng vệ sinh quần (30116, 30115) trị giá 50K | F12: 83 | G12: 178 | H12: 9 | I12: =MIN(ROUNDUP(G12/MAX(1,24-H12),0),ROUNDDOWN(F12/H12,0)) -> 9 | J12: Store JP Nguyễn Du, Store JP Hàng Bông, Store JP Nguyễn Tuân, Store JP Ngoại Giao Đoàn, Store JP Nguyễn Văn Lộc, SKK Vinhome Green Bay, SKK Xuân La, SKK Sài Đồng, SKK Bắc Ninh
A13: CT001 | B13: THỜI TRANG | C13: 142036 | D13: NISHIMATSUYA- Bộ Đồ Body Liền Thân Trẻ em Nhật Bản | E13: Thời trang Nishimatsuya mùa đông giảm ngay 20% | F13: 320 | G13: 897 | H13: 8 | I13: =MIN(ROUNDUP(G13/MAX(1,24-H13),0),ROUNDDOWN(F13/H13,0)) -> 40 | J13: CVS 108-110 Linh Lang, Store JP Linh Đàm, Store JP Trần Đăng Ninh, SKK Trần Duy Hưng, Store JP Ecohome 3, SKK Vinhome Green Bay, SKK Xuân La, CVS 34 Vũ Phạm Hàm
A14: CT028 | B14: CHĂM SÓC HÀNG NGÀY | C14: 110389 | D14: KAO- BVS Laurier hàng ngày không mùi (72 m) | E14: Băng vệ sinh hằng ngày Laurier 72 miếng giá chỉ còn 79k | F14: 120 | G14: 90 | H14: 7 | I14: =MIN(ROUNDUP(G14/MAX(1,24-H14),0),ROUNDDOWN(F14/H14,0)) -> 6 | J14: Store JP Đội Cấn, Store JP Thái Hà, Store JP Trần Đăng Ninh, Store JP Hàm Nghi, Store JP Nguyễn Tuân, Store JP Ngoại Giao Đoàn, CVS 34 Vũ Phạm Hàm
A15: CT004 | B15: NHÀ CỬA ĐỜI SỐNG | C15: 134230 | D15: KAO- Nước rửa bát Kyukyuto không mùi 1250ml | E15: Nước rửa bát 1250ml giá 188k->159K | F15: 12 | G15: 169 | H15: 7 | I15: =MIN(ROUNDUP(G15/MAX(1,24-H15),0),ROUNDDOWN(F15/H15,0)) -> 1 | J15: Store JP Mandarin C1, Store JP Thái Hà, Store JP Nguyễn Du, Store JP Hàng Bông, Store JP Văn Phú, Store JP T6 Time City, Store JP Ecohome 3
... A135: CT038 | B135: CHĂM SÓC SẮC ĐẸP | C135: 101828 | D135: KUMANO-Dầu gội Pharmaact Men's siêu mát 600ml | E135: Mua tắm gội Pharmaact Men's được tặng ngay 1 SRM nam trị giá 90K (230792) | F135: 3 | G135: 256 | H135: 1 | I135: =MIN(ROUNDUP(G135/MAX(1,24-H135),0),ROUNDDOWN(F135/H135,0)) -> 3 | J135: CVS 34 Vũ Phạm Hàm
A137: Gợi ý cấp/CH thiếu = min(tồn TB của các CH đang có hàng, Kho LTT chia đều cho CH thiếu). Là con số khởi điểm – ngành hàng chỉnh theo sell-out thực tế.

Sheet Ma trận phủ CH
A1: MA TRẬN TỒN SKU KM CHỦ LỰC × CỬA HÀNG (ô đỏ = 0/âm). SKU chủ lực = tồn HT ≥50, trừ giày & KAI/KAIYO.
A3: Mã CT | B3: Ngành hàng | C3: Item | D3: Tên SP | E3: Kho LTT | F3: CVS 108-110 Linh Lang | G3: Store JP Đội Cấn | H3: Store JP Linh Đàm | I3: Store JP Mandarin C1 | J3: Store JP Thái Hà | K3: Store JP Trần Đăng Ninh | L3: Store JP Nguyễn Du | M3: Store JP Hàng Bông | N3: Store JP Văn Phú | O3: Store JP Hàm Nghi | P3: Store JP Nguyễn Tuân | Q3: Store JP Đỗ Quang | R3: Store JP Ngoại Giao Đoàn | S3: SKK Trần Duy Hưng | T3: Store JP Nguyễn Văn Lộc | U3: Store JP T6 Time City | V3: Store JP Ecohome 3 | W3: SKK Vinhome Green Bay | X3: SKK Xuân La | Y3: SKK Nguyễn Khuyến | Z3: SKK Sài Đồng | AA3: SKK Bạch Mai | AB3: SKK Vũ Phạm Hàm | AC3: SKK Bắc Ninh | AD3: CVS 34 Vũ Phạm Hàm | AE3: Số CH = 0
A4: CT005 | B4: BÁNH NGỌT - TRÁNG MIỆNG | C4: 151049 | D4: FUTABA- Kem vani sandwich | E4: 0 | F4: 32 | G4: 32 | H4: 49 | I4: 1 | J4: 0 | K4: 69 | L4: 18 | M4: 36 | N4: 0 | O4: 3 | P4: 18 | Q4: 4 | R4: 6 | S4: 37 | T4: 8 | U4: 79 | V4: 17 | W4: 0 | X4: 6 | Y4: 0 | Z4: 14 | AA4: 0 | AB4: 0 | AC4: 0 | AD4: 40 | AE4: =COUNTIF(F4:AD4,"<=0") -> 7
A5: CT005 | B5: BÁNH NGỌT - TRÁNG MIỆNG | C5: 151051 | D5: LOTTE- Kem vani Daifuku | E5: 0 | F5: 22 | G5: 67 | H5: 50 | I5: 27 | J5: 22 | K5: 20 | L5: 20 | M5: 28 | N5: 37 | O5: 36 | P5: 2 | Q5: 15 | R5: 43 | S5: 11 | T5: 21 | U5: 74 | V5: 6 | W5: 0 | X5: 14 | Y5: 0 | Z5: 9 | AA5: 16 | AB5: 0 | AC5: 0 | AD5: 9 | AE5: =COUNTIF(F5:AD5,"<=0") -> 4
A6: CT005 | B6: BÁNH NGỌT - TRÁNG MIỆNG | C6: 151565 | D6: FUTABA- Kem Sandwich Hokkaido | E6: 0 | F6: 12 | G6: 37 | H6: 39 | I6: 21 | J6: 5 | K6: 2 | L6: 34 | M6: 13 | N6: 16 | O6: 23 | P6: 16 | Q6: 6 | R6: 47 | S6: 18 | T6: 7 | U6: 46 | V6: 8 | W6: 0 | X6: 47 | Y6: 0 | Z6: 8 | AA6: 13 | AB6: 0 | AC6: 0 | AD6: 18 | AE6: =COUNTIF(F6:AD6,"<=0") -> 4
A7: CT005 | B7: BÁNH NGỌT - TRÁNG MIỆNG | C7: 151724 | D7: MORINAGA- Kem Chocolate Ice | E7: 0 | F7: 18 | G7: 14 | H7: 39 | I7: 13 | J7: 17 | K7: 30 | L7: 0 | M7: 47 | N7: 24 | O7: 4 | P7: 11 | Q7: 0 | R7: 39 | S7: 0 | T7: 26 | U7: 50 | V7: 13 | W7: 0 | X7: 0 | Y7: 0 | Z7: 10 | AA7: 11 | AB7: 0 | AC7: 0 | AD7: 31 | AE7: =COUNTIF(F7:AD7,"<=0") -> 8
A8: CT005 | B8: BÁNH NGỌT - TRÁNG MIỆNG | C8: 174761 | D8: FUTABA - Kem Tiramisu bọc sô cô la 115ml | E8: 0 | F8: 0 | G8: 8 | H8: 6 | I8: 2 | J8: 0 | K8: 0 | L8: 0 | M8: 6 | N8: 0 | O8: 0 | P8: 0 | Q8: 23 | R8: 0 | S8: 0 | T8: 0 | U8: 13 | V8: 5 | W8: 0 | X8: 0 | Y8: 0 | Z8: 0 | AA8: 14 | AB8: 0 | AC8: 0 | AD8: 0 | AE8: =COUNTIF(F8:AD8,"<=0") -> 17
A9: CT005 | B9: BÁNH NGỌT - TRÁNG MIỆNG | C9: 174763 | D9: NAGANUMA - Kem ly vị sữa tươi 100ml | E9: 0 | F9: 23 | G9: 0 | H9: 18 | I9: 9 | J9: 0 | K9: 0 | L9: 0 | M9: 0 | N9: 0 | O9: 24 | P9: 23 | Q9: 0 | R9: 11 | S9: 0 | T9: 14 | U9: 27 | V9: 0 | W9: 0 | X9: 0 | Y9: 0 | Z9: 6 | AA9: 0 | AB9: 0 | AC9: 0 | AD9: 23 | AE9: =COUNTIF(F9:AD9,"<=0") -> 15
A10: CT005 | B10: BÁNH NGỌT - TRÁNG MIỆNG | C10: 174764 | D10: NAGANUMA - Kem ly vị Phô mai 100ml | E10: 0 | F10: 23 | G10: 22 | H10: 40 | I10: 3 | J10: 3 | K10: 42 | L10: 0 | M10: 20 | N10: 0 | O10: 45 | P10: 24 | Q10: 24 | R10: 3 | S10: 0 | T10: 21 | U10: 25 | V10: 65 | W10: 0 | X10: 0 | Y10: 0 | Z10: 6 | AA10: 23 | AB10: 0 | AC10: 0 | AD10: 25 | AE10: =COUNTIF(F10:AD10,"<=0") -> 8
A11: CT005 | B11: BÁNH NGỌT - TRÁNG MIỆNG | C11: 174765 | D11: NAGANUMA - Kem ly vị Sô cô la 100ml | E11: 0 | F11: 21 | G11: 18 | H11: 34 | I11: 20 | J11: 2 | K11: 22 | L11: 0 | M11: 7 | N11: 0 | O11: 18 | P11: 25 | Q11: 12 | R11: 6 | S11: 0 | T11: 7 | U11: 21 | V11: 0 | W11: 0 | X11: 0 | Y11: 0 | Z11: 2 | AA11: 21 | AB11: 0 | AC11: 0 | AD11: 4 | AE11: =COUNTIF(F11:AD11,"<=0") -> 9
A12: CT005 | B12: BÁNH NGỌT - TRÁNG MIỆNG | C12: 174766 | D12: NAGANUMA - Kem ly vị Trà xanh 100ml | E12: 0 | F12: 21 | G12: 19 | H12: 11 | I12: -2 | J12: 2 | K12: 19 | L12: 7 | M12: 14 | N12: 0 | O12: 26 | P12: 2 | Q12: 0 | R12: 13 | S12: 0 | T12: 19 | U12: 41 | V12: 14 | W12: 0 | X12: 0 | Y12: 0 | Z12: 0 | AA12: 23 | AB12: 0 | AC12: 0 | AD12: 2 | AE12: =COUNTIF(F12:AD12,"<=0") -> 10
A13: CT005 | B13: BÁNH NGỌT - TRÁNG MIỆNG | C13: 152392 | D13: FUTABA- Kem socola Dandy 160ml | E13: 0 | F13: 10 | G13: 19 | H13: 2 | I13: 21 | J13: 14 | K13: 0 | L13: 44 | M13: 13 | N13: 0 | O13: 19 | P13: 10 | Q13: 0 | R13: 13 | S13: 0 | T13: 10 | U13: 4 | V13: 13 | W13: 0 | X13: 0 | Y13: 0 | Z13: 25 | AA13: 21 | AB13: 0 | AC13: 0 | AD13: 18 | AE13: =COUNTIF(F13:AD13,"<=0") -> 9
A14: CT005 | B14: BÁNH NGỌT - TRÁNG MIỆNG | C14: 152557 | D14: FUTABA- Kem cà phê latte Kaoru 60mlx5c | E14: 0 | F14: 5 | G14: 15 | H14: 0 | I14: 8 | J14: 7 | K14: 9 | L14: 13 | M14: 13 | N14: 0 | O14: 16 | P14: 0 | Q14: 0 | R14: 0 | S14: 0 | T14: 5 | U14: 13 | V14: 1 | W14: 0 | X14: 8 | Y14: 0 | Z14: 8 | AA14: 12 | AB14: 0 | AC14: 0 | AD14: 8 | AE14: =COUNTIF(F14:AD14,"<=0") -> 10
A15: CT005 | B15: BÁNH NGỌT - TRÁNG MIỆNG | C15: 152872 | D15: MORINAGA- Kem pari pari choco (Hộp 8 chiếc) | E15: 0 | F15: 6 | G15: 14 | H15: 0 | I15: 2 | J15: 4 | K15: 0 | L15: 25 | M15: 9 | N15: 10 | O15: 11 | P15: 1 | Q15: 0 | R15: 34 | S15: 3 | T15: 7 | U15: 17 | V15: 5 | W15: 0 | X15: 19 | Y15: 0 | Z15: 1 | AA15: 10 | AB15: 0 | AC15: 0 | AD15: 0 | AE15: =COUNTIF(F15:AD15,"<=0") -> 8
... A409: CT082 | B409: ĐỒ UỐNG | C409: 152336 | D409: AGF- Cà phê hòa tan Blendy Stick vị sữa 8 thanh | E409: 0 | F409: 0 | G409: 0 | H409: 0 | I409: 0 | J409: 0 | K409: 0 | L409: 0 | M409: -8 | N409: 0 | O409: 12 | P409: 7 | Q409: 0 | R409: 0 | S409: 1 | T409: 0 | U409: 3 | V409: 0 | W409: 5 | X409: 0 | Y409: 0 | Z409: 27 | AA409: 0 | AB409: 0 | AC409: 0 | AD409: 0 | AE409: =COUNTIF(F409:AD409,"<=0") -> 19
D410: Số SKU chủ lực = 0 tại CH | F410: =COUNTIF(F4:F409,"<=0") -> 227 | G410: =COUNTIF(G4:G409,"<=0") -> 41 | H410: =COUNTIF(H4:H409,"<=0") -> 53 | I410: =COUNTIF(I4:I409,"<=0") -> 47 | J410: =COUNTIF(J4:J409,"<=0") -> 56 | K410: =COUNTIF(K4:K409,"<=0") -> 44 | L410: =COUNTIF(L4:L409,"<=0") -> 64 | M410: =COUNTIF(M4:M409,"<=0") -> 57 | ... AD410: =COUNTIF(AD4:AD409,"<=0") -> 309
D411: % phủ SKU chủ lực | F411: =1-F410/406 -> 0.4408867 | G411: =1-G410/406 -> 0.89901478 | H411: =1-H410/406 -> 0.86945813 | I411: =1-I410/406 -> 0.88423645 | J411: =1-J410/406 -> 0.86206897 | K411: =1-K410/406 -> 0.89162562 | L411: =1-L410/406 -> 0.84236453 | M411: =1-M410/406 -> 0.85960591 | ... AD411: =1-AD410/406 -> 0.23891626

Sheet SKU KM hết hàng
A1: Mã CT | B1: Ngành hàng | C1: Item | D1: Tên SP | E1: Trạng thái KD | F1: Nội dung CTKM | G1: Có trong file tồn?
A2: CT005 | B2: BÁNH NGỌT - TRÁNG MIỆNG | C2: 154140 | D2: FUTABA- Kem ly Sacre vị chanh | E2: NGỪNG NHẬP | F2: Kem đồng giảm 8% | G2: Không
A3: CT090 | B3: BỈM | C3: 173649 | D3: MERRIES- Bỉm quần XXL 26 miếng | E3: NGỪNG SẢN XUẤT - RENEW | F3: Bỉm merries bao bì cũ xả hàng giá 199K | G3: Không
A4: CT090 | B4: BỈM | C4: 173650 | D4: MERRIES- Bỉm dán M 64 miếng | E4: NGỪNG SẢN XUẤT - RENEW | F4: Bỉm merries bao bì cũ xả hàng giá 199K | G4: Không
A5: CT090 | B5: BỈM | C5: 173651 | D5: MERRIES- Bỉm quần M 58 miếng | E5: NGỪNG SẢN XUẤT - RENEW | F5: Bỉm merries bao bì cũ xả hàng giá 199K | G5: Không
A6: CT090 | B6: BỈM | C6: 173688 | D6: MERRIES- Bỉm dán SS 90 miếng | E6: NGỪNG SẢN XUẤT - RENEW | F6: Bỉm merries bao bì cũ xả hàng giá 199K | G6: Không
A7: CT090 | B7: BỈM | C7: 173689 | D7: MERRIES- Bỉm dán S 82 miếng | E7: NGỪNG SẢN XUẤT - RENEW | F7: Bỉm merries bao bì cũ xả hàng giá 199K | G7: Không
A8: CT090 | B8: BỈM | C8: 220024 | D8: MERRIES- Bỉm quần XL 38 + 6 miếng | E8: NGỪNG SẢN XUẤT - RENEW | F8: Bỉm merries bao bì cũ xả hàng giá 199K | G8: Không
A9: CT090 | B9: BỈM | C9: 220047 | D9: MERRIES- BỈM QUẦN XL 38+6 MIẾNG | E9: NGỪNG SẢN XUẤT - RENEW | F9: Bỉm merries bao bì cũ xả hàng giá 199K | G9: Không
A10: CT090 | B10: BỈM | C10: 220006 | D10: MERRIES- Bỉm quần XL 38 + 6 miếng | E10: NGỪNG SẢN XUẤT - RENEW | F10: Bỉm merries bao bì cũ xả hàng giá 199K | G10: Không
A11: CT090 | B11: BỈM | C11: 220007 | D11: MERRIES- Bỉm quần XXL 26+2 miếng | E11: NGỪNG SẢN XUẤT - RENEW | F11: Bỉm merries bao bì cũ xả hàng giá 199K | G11: Không
A12: CT090 | B12: BỈM | C12: 220008 | D12: MERRIES- Bỉm dán M 64+4 miếng | E12: NGỪNG SẢN XUẤT - RENEW | F12: Bỉm merries bao bì cũ xả hàng giá 199K | G12: Không
A13: CT090 | B13: BỈM | C13: 220015 | D13: MERRIES- Bỉm dán SS 90+6 miếng | E13: NGỪNG SẢN XUẤT - RENEW | F13: Bỉm merries bao bì cũ xả hàng giá 199K | G13: Không
... A188: CT063 | B188: THỜI TRANG | C188: 143296 | D188: PARTIRD'ABORD-Dép đế xuồng quai lưới M-Gỗ sồi | E188: HÀNG NEW | F188: Giảm ngay 250K khi mua giày cao cấp Nhật Bản | G188: Không

Sheet Rủi ro biên FC
A1: SKU có lợi nhuận FC âm khi bán giá KM (Giá KM < Giá FC chốt). Phạm vi "Toàn hệ thống" = áp cho cả nhượng quyền → CH FC bán là lỗ.
A3: Phạm vi | B3: Ngành hàng | C3: Item | D3: Tên SP | E3: Nội dung CTKM | F3: Giá BL | G3: Giá FC chốt | H3: Giá KM | I3: LN FC/sp | J3: %LN FC | K3: Kho FC
A4: Toàn hệ thống | B4: ĐỒ UỐNG | C4: 154470 | D4: SATOEN- Hộp trà Sencha Genmai 50g (20 túi x 2.5g) | E4: Trà AGF, Satoen giá chỉ còn 39k (Xả tồn) | F4: 155000 | G4: 95000 | H4: 39000 | I4: =H4-G4 -> -56000 | J4: =IFERROR(I4/H4,0) -> -1.4358974 | K4: 0
A5: Toàn hệ thống | B5: ĐỒ UỐNG | C5: 154466 | D5: SATOEN- Hộp trà Sencha Special 80g | E5: Trà AGF, Satoen giá chỉ còn 39k (Xả tồn) | F5: 115000 | G5: 74000 | H5: 39000 | I5: =H5-G5 -> -35000 | J5: =IFERROR(I5/H5,0) -> -0.8974359 | K5: 0
A6: Toàn hệ thống | B6: CHĂM SÓC SẮC ĐẸP | C6: 101962 | D6: LSC-Lotion trà xanh 500ml | E6: Tẩy trang, Lotion LSC đồng giá 99K | F6: 285000 | G6: 185000 | H6: 100000 | I6: =H6-G6 -> -85000 | J6: =IFERROR(I6/H6,0) -> -0.85 | K6: 0
A7: Toàn hệ thống | B7: ĐỒ UỐNG | C7: 154463 | D7: SATOEN- Hộp trà Sencha Special 40g (20 túi x 2g) | E7: Trà AGF, Satoen giá chỉ còn 39k (Xả tồn) | F7: 115000 | G7: 70000 | H7: 39000 | I7: =H7-G7 -> -31000 | J7: =IFERROR(I7/H7,0) -> -0.79487179 | K7: 0
A8: Toàn hệ thống | B8: CHĂM SÓC SẮC ĐẸP | C8: 101963 | D8: LSC- Tẩy trang trà xanh 250g | E8: Tẩy trang, Lotion LSC đồng giá 99K | F8: 325000 | G8: 176300 | H8: 100000 | I8: =H8-G8 -> -76300 | J8: =IFERROR(I8/H8,0) -> -0.763 | K8: 0
